Workbook

Sheet CODORL
O1: códigos ok
O2: VISITADOR | P2: INICIALES | Q2: CODORL | R2: TIPO | S2: NOMBRE ORL | T2: Nombre | U2: CONTROLVENTAS
O3: Maika Blázquez (Madrid) | P3: MBM | Q3: MBM187 | R3: A | S3: Dr, Abel Bogoya Castaño | T3: Abel Bogoya Castaño | U3: MBM187
O4: Ramon Ferrando(Valencia) | P4: RFV | Q4: RFV08 | R4: B | S4: Dr, Abel Guzmán Calvete | T4: Abel Guzmán Calvete | U4: RFV08
O5: Maika Blázquez (Madrid) | P5: MBM | Q5: MBM86 | R5: A | S5: Dra, Adela Cordero Devesa | T5: Adela Cordero Devesa | U5: MBM86
O6: Roberto Pereira (Galicia) | P6: RPG | Q6: RPG33 | R6: A | S6: Dra, Adela Pérez-Caro Ríos | T6: Adela Pérez-Caro Ríos | U6: RPG33
O7: Lisandro Russian (Madrid,Cáceres, Toledo, Talavera y Logroño) | P7: LRM | Q7: LRM01 | R7: A | S7: Dr, Adolfo Carlos Hinojar Gutierrez | T7: Adolfo Carlos Hinojar Gutierrez | U7: LRM01
O8: Alberto Moreno | P8: AMM | Q8: AMM01 | R8: A | S8: Dr, Adolfo del Valle Zapico | T8: Adolfo del Valle Zapico | U8: AMM01
O9: Maika Blázquez (Madrid) | P9: MBM | Q9: MBM01 | R9: A | S9: Dr, Adolfo Toledano Muñoz | T9: Adolfo Toledano Muñoz | U9: MBM01
O10: Lisandro Russian (Madrid,Cáceres, Toledo, Talavera y Logroño) | P10: LRM | Q10: LRM123 | R10: A | S10: Dra, Adriana Pardo Maza | T10: Adriana Pardo Maza | U10: LRM123
O11: Maika Blázquez (Madrid) | P11: MBM | Q11: MBM87 | R11: A | S11: Dra, Adriana Pérez García | T11: Adriana Pérez García | U11: MBM87
O12: Iván Sánchez (Levante y Albacete) | P12: ISL | Q12: ISL82 | R12: B | S12: Dra, Africa Jiménez de la Rosa | T12: Africa Jiménez de la Rosa | U12: ISL82
O13: Ramon Ferrando(Valencia) | P13: RFV | Q13: RFV09 | R13: B | S13: Dr, Agustín Campos Catalá | T13: Agustín Campos Catalá | U13: RFV09
... O931: Ramon Ferrando(Valencia) | P931: RFV | Q931: RFV45 | R931: B | S931: Dr, Ángel Ángel de Miguel | T931: Ángel Ángel de Miguel | U931: RFV45
O932: Lisandro Russian (Madrid, Cáceres, Toledo, Talavera Y Logroño) | P932: LRM | Q932: LRM259 | R932: A | S932: Dr, Carlos Montero García | T932: Carlos Montero García | U932: =Q932 -> LRM259

Sheet códigosORL
F1: Códigos actualizados
F5: =IFERROR(__xludf.DUMMYFUNCTION("QUERY(IMPORTRANGE(""1vYjGeYY0Fv1uPTb97Gbjvlxd4khfYQOQJB5UlsSt3ZY/edit?gid=0#gid=0"",""CODORL!A:F""),""SELECT *"",2)"),"🟢 Introduce los datos en la fila 3 y pulsa el botón para generar el código ORL VISITADOR") -> 🟢 Introduce los datos en la fila 3 y pulsa el botón para generar el código ORL VISITADOR | G5: =IFERROR(__xludf.DUMMYFUNCTION("""COMPUTED_VALUE""")," INICIALES") -> INICIALES | H5: =IFERROR(__xludf.DUMMYFUNCTION("""COMPUTED_VALUE""")," CODORL") -> CODORL | I5: =IFERROR(__xludf.DUMMYFUNCTION("""COMPUTED_VALUE""")," TIPO") -> TIPO | J5: =IFERROR(__xludf.DUMMYFUNCTION("""COMPUTED_VALUE""")," NOMBRE ORL") -> NOMBRE ORL | K5: =IFERROR(__xludf.DUMMYFUNCTION("""COMPUTED_VALUE""")," OBSERVACIONES") -> OBSERVACIONES
F7: =IFERROR(__xludf.DUMMYFUNCTION("""COMPUTED_VALUE"""),"Luis Alberto Rodríguez") -> Luis Alberto Rodríguez | G7: =IFERROR(__xludf.DUMMYFUNCTION("""COMPUTED_VALUE"""),"LAA") -> LAA | H7: =IFERROR(__xludf.DUMMYFUNCTION("""COMPUTED_VALUE"""),"LAA91") -> LAA91 | I7: =IFERROR(__xludf.DUMMYFUNCTION("""COMPUTED_VALUE"""),"C") -> C | J7: =IFERROR(__xludf.DUMMYFUNCTION("""COMPUTED_VALUE"""),"Julio César Ariza Lizcano") -> Julio César Ariza Lizcano | L7: =H7 -> LAA91 | M7: =G7 -> LAA
F8: =IFERROR(__xludf.DUMMYFUNCTION("""COMPUTED_VALUE"""),"Lisandro Russian") -> Lisandro Russian | G8: =IFERROR(__xludf.DUMMYFUNCTION("""COMPUTED_VALUE"""),"LRM") -> LRM | H8: =IFERROR(__xludf.DUMMYFUNCTION("""COMPUTED_VALUE"""),"LRM274") -> LRM274 | I8: =IFERROR(__xludf.DUMMYFUNCTION("""COMPUTED_VALUE"""),"A") -> A | J8: =IFERROR(__xludf.DUMMYFUNCTION("""COMPUTED_VALUE"""),"Ane Díez Fernández") -> Ane Díez Fernández | L8: =H8 -> LRM274 | M8: =G8 -> LRM
F9: =IFERROR(__xludf.DUMMYFUNCTION("""COMPUTED_VALUE"""),"Maika Blázquez") -> Maika Blázquez | G9: =IFERROR(__xludf.DUMMYFUNCTION("""COMPUTED_VALUE"""),"MBM") -> MBM | H9: =IFERROR(__xludf.DUMMYFUNCTION("""COMPUTED_VALUE"""),"MBM235") -> MBM235 | I9: =IFERROR(__xludf.DUMMYFUNCTION("""COMPUTED_VALUE"""),"A") -> A | J9: =IFERROR(__xludf.DUMMYFUNCTION("""COMPUTED_VALUE"""),"Andrés Bejarano Bueno") -> Andrés Bejarano Bueno | L9: =H9 -> MBM235 | M9: =G9 -> MBM
F10: =IFERROR(__xludf.DUMMYFUNCTION("""COMPUTED_VALUE"""),"Iván Sánchez") -> Iván Sánchez | G10: =IFERROR(__xludf.DUMMYFUNCTION("""COMPUTED_VALUE"""),"ISL") -> ISL | H10: =IFERROR(__xludf.DUMMYFUNCTION("""COMPUTED_VALUE"""),"ISL155") -> ISL155 | I10: =IFERROR(__xludf.DUMMYFUNCTION("""COMPUTED_VALUE"""),"B") -> B | J10: =IFERROR(__xludf.DUMMYFUNCTION("""COMPUTED_VALUE"""),"Andreina Betancourt Martínez") -> Andreina Betancourt Martínez | L10: =H10 -> ISL155 | M10: =G10 -> ISL
F11: =IFERROR(__xludf.DUMMYFUNCTION("""COMPUTED_VALUE"""),"Maika Blázquez") -> Maika Blázquez | G11: =IFERROR(__xludf.DUMMYFUNCTION("""COMPUTED_VALUE"""),"MBM") -> MBM | H11: =IFERROR(__xludf.DUMMYFUNCTION("""COMPUTED_VALUE"""),"MBM234") -> MBM234 | I11: =IFERROR(__xludf.DUMMYFUNCTION("""COMPUTED_VALUE"""),"A") -> A | J11: =IFERROR(__xludf.DUMMYFUNCTION("""COMPUTED_VALUE"""),"Andrea López") -> Andrea López | L11: =H11 -> MBM234 | M11: =G11 -> MBM
F12: =IFERROR(__xludf.DUMMYFUNCTION("""COMPUTED_VALUE"""),"Maika Blázquez") -> Maika Blázquez | G12: =IFERROR(__xludf.DUMMYFUNCTION("""COMPUTED_VALUE"""),"MBM") -> MBM | H12: =IFERROR(__xludf.DUMMYFUNCTION("""COMPUTED_VALUE"""),"MBM233") -> MBM233 | I12: =IFERROR(__xludf.DUMMYFUNCTION("""COMPUTED_VALUE"""),"A") -> A | J12: =IFERROR(__xludf.DUMMYFUNCTION("""COMPUTED_VALUE"""),"Ana Clemente Arias") -> Ana Clemente Arias | L12: =H12 -> MBM233 | M12: =G12 -> MBM
F13: =IFERROR(__xludf.DUMMYFUNCTION("""COMPUTED_VALUE"""),"Luis Alberto Rodríguez") -> Luis Alberto Rodríguez | G13: =IFERROR(__xludf.DUMMYFUNCTION("""COMPUTED_VALUE"""),"LAA") -> LAA | H13: =IFERROR(__xludf.DUMMYFUNCTION("""COMPUTED_VALUE"""),"LAA90") -> LAA90 | I13: =IFERROR(__xludf.DUMMYFUNCTION("""COMPUTED_VALUE"""),"C") -> C | J13: =IFERROR(__xludf.DUMMYFUNCTION("""COMPUTED_VALUE"""),"Amparo Postigo Madueño") -> Amparo Postigo Madueño | L13: =H13 -> LAA90 | M13: =G13 -> LAA
F14: =IFERROR(__xludf.DUMMYFUNCTION("""COMPUTED_VALUE"""),"Maika Blázquez") -> Maika Blázquez | G14: =IFERROR(__xludf.DUMMYFUNCTION("""COMPUTED_VALUE"""),"MBM") -> MBM | H14: =IFERROR(__xludf.DUMMYFUNCTION("""COMPUTED_VALUE"""),"MBM232") -> MBM232 | I14: =IFERROR(__xludf.DUMMYFUNCTION("""COMPUTED_VALUE"""),"A") -> A | J14: =IFERROR(__xludf.DUMMYFUNCTION("""COMPUTED_VALUE"""),"Ali Ibrahim Farhat") -> Ali Ibrahim Farhat | L14: =H14 -> MBM232 | M14: =G14 -> MBM
F15: =IFERROR(__xludf.DUMMYFUNCTION("""COMPUTED_VALUE"""),"Maika Blázquez") -> Maika Blázquez | G15: =IFERROR(__xludf.DUMMYFUNCTION("""COMPUTED_VALUE"""),"MBM") -> MBM | H15: =IFERROR(__xludf.DUMMYFUNCTION("""COMPUTED_VALUE"""),"MBM231") -> MBM231 | I15: =IFERROR(__xludf.DUMMYFUNCTION("""COMPUTED_VALUE"""),"A") -> A | J15: =IFERROR(__xludf.DUMMYFUNCTION("""COMPUTED_VALUE"""),"Itziar Jimenez Gomez") -> Itziar Jimenez Gomez | L15: =H15 -> MBM231 | M15: =G15 -> MBM
F16: =IFERROR(__xludf.DUMMYFUNCTION("""COMPUTED_VALUE"""),"Iván Sánchez") -> Iván Sánchez | G16: =IFERROR(__xludf.DUMMYFUNCTION("""COMPUTED_VALUE"""),"ISL") -> ISL | H16: =IFERROR(__xludf.DUMMYFUNCTION("""COMPUTED_VALUE"""),"ISL154") -> ISL154 | I16: =IFERROR(__xludf.DUMMYFUNCTION("""COMPUTED_VALUE"""),"B") -> B | J16: =IFERROR(__xludf.DUMMYFUNCTION("""COMPUTED_VALUE"""),"Alfonso Rodríguez Fabio") -> Alfonso Rodríguez Fabio | L16: =H16 -> ISL154 | M16: =G16 -> ISL
F17: =IFERROR(__xludf.DUMMYFUNCTION("""COMPUTED_VALUE"""),"Iván Sánchez") -> Iván Sánchez | G17: =IFERROR(__xludf.DUMMYFUNCTION("""COMPUTED_VALUE"""),"ISL") -> ISL | H17: =IFERROR(__xludf.DUMMYFUNCTION("""COMPUTED_VALUE"""),"ISL153") -> ISL153 | I17: =IFERROR(__xludf.DUMMYFUNCTION("""COMPUTED_VALUE"""),"B") -> B | J17: =IFERROR(__xludf.DUMMYFUNCTION("""COMPUTED_VALUE"""),"Alejandra Arellano Bárcenas") -> Alejandra Arellano Bárcenas | L17: =H17 -> ISL153 | M17: =G17 -> ISL
F18: =IFERROR(__xludf.DUMMYFUNCTION("""COMPUTED_VALUE"""),"Lisandro Russian") -> Lisandro Russian | G18: =IFERROR(__xludf.DUMMYFUNCTION("""COMPUTED_VALUE"""),"LRM") -> LRM | H18: =IFERROR(__xludf.DUMMYFUNCTION("""COMPUTED_VALUE"""),"LRM273") -> LRM273 | I18: =IFERROR(__xludf.DUMMYFUNCTION("""COMPUTED_VALUE"""),"A") -> A | J18: =IFERROR(__xludf.DUMMYFUNCTION("""COMPUTED_VALUE"""),"Ainhoa Leceta Sáez de Cámara") -> Ainhoa Leceta Sáez de Cámara | L18: =H18 -> LRM273 | M18: =G18 -> LRM
F19: =IFERROR(__xludf.DUMMYFUNCTION("""COMPUTED_VALUE"""),"Luis Alberto Rodríguez") -> Luis Alberto Rodríguez | G19: =IFERROR(__xludf.DUMMYFUNCTION("""COMPUTED_VALUE"""),"LAA") -> LAA | H19: =IFERROR(__xludf.DUMMYFUNCTION("""COMPUTED_VALUE"""),"LAA89") -> LAA89 | I19: =IFERROR(__xludf.DUMMYFUNCTION("""COMPUTED_VALUE"""),"C") -> C | J19: =IFERROR(__xludf.DUMMYFUNCTION("""COMPUTED_VALUE"""),"Agustín Alcalá Fernández") -> Agustín Alcalá Fernández | L19: =H19 -> LAA89 | M19: =G19 -> LAA
F20: =IFERROR(__xludf.DUMMYFUNCTION("""COMPUTED_VALUE"""),"Maika Blázquez") -> Maika Blázquez | G20: =IFERROR(__xludf.DUMMYFUNCTION("""COMPUTED_VALUE"""),"MBM") -> MBM | H20: =IFERROR(__xludf.DUMMYFUNCTION("""COMPUTED_VALUE"""),"MBM187") -> MBM187 | I20: =IFERROR(__xludf.DUMMYFUNCTION("""COMPUTED_VALUE"""),"A") -> A | J20: =IFERROR(__xludf.DUMMYFUNCTION("""COMPUTED_VALUE"""),"Abel Bogoya Castaño") -> Abel Bogoya Castaño | L20: =H20 -> MBM187 | M20: =G20 -> MBM
F21: =IFERROR(__xludf.DUMMYFUNCTION("""COMPUTED_VALUE"""),"Ramon Ferrando") -> Ramon Ferrando | G21: =IFERROR(__xludf.DUMMYFUNCTION("""COMPUTED_VALUE"""),"RFV") -> RFV | H21: =IFERROR(__xludf.DUMMYFUNCTION("""COMPUTED_VALUE"""),"RFV08") -> RFV08 | I21: =IFERROR(__xludf.DUMMYFUNCTION("""COMPUTED_VALUE"""),"B") -> B | J21: =IFERROR(__xludf.DUMMYFUNCTION("""COMPUTED_VALUE"""),"Abel Guzmán Calvete") -> Abel Guzmán Calvete | L21: =H21 -> RFV08 | M21: =G21 -> RFV
F22: =IFERROR(__xludf.DUMMYFUNCTION("""COMPUTED_VALUE"""),"Maika Blázquez") -> Maika Blázquez | G22: =IFERROR(__xludf.DUMMYFUNCTION("""COMPUTED_VALUE"""),"MBM") -> MBM | H22: =IFERROR(__xludf.DUMMYFUNCTION("""COMPUTED_VALUE"""),"MBM86") -> MBM86 | I22: =IFERROR(__xludf.DUMMYFUNCTION("""COMPUTED_VALUE"""),"A") -> A | J22: =IFERROR(__xludf.DUMMYFUNCTION("""COMPUTED_VALUE"""),"Adela Cordero Devesa") -> Adela Cordero Devesa | L22: =H22 -> MBM86 | M22: =G22 -> MBM
F23: =IFERROR(__xludf.DUMMYFUNCTION("""COMPUTED_VALUE"""),"Roberto Pereira") -> Roberto Pereira | G23: =IFERROR(__xludf.DUMMYFUNCTION("""COMPUTED_VALUE"""),"RPG") -> RPG | H23: =IFERROR(__xludf.DUMMYFUNCTION("""COMPUTED_VALUE"""),"RPG33") -> RPG33 | I23: =IFERROR(__xludf.DUMMYFUNCTION("""COMPUTED_VALUE"""),"A") -> A | J23: =IFERROR(__xludf.DUMMYFUNCTION("""COMPUTED_VALUE"""),"Adela Pérez-Caro Ríos") -> Adela Pérez-Caro Ríos | L23: =H23 -> RPG33 | M23: =G23 -> RPG
F24: =IFERROR(__xludf.DUMMYFUNCTION("""COMPUTED_VALUE"""),"Lisandro Russian") -> Lisandro Russian | G24: =IFERROR(__xludf.DUMMYFUNCTION("""COMPUTED_VALUE"""),"LRM") -> LRM | H24: =IFERROR(__xludf.DUMMYFUNCTION("""COMPUTED_VALUE"""),"LRM01") -> LRM01 | I24: =IFERROR(__xludf.DUMMYFUNCTION("""COMPUTED_VALUE"""),"A") -> A | J24: =IFERROR(__xludf.DUMMYFUNCTION("""COMPUTED_VALUE"""),"Adolfo Carlos Hinojar Gutierrez") -> Adolfo Carlos Hinojar Gutierrez | L24: =H24 -> LRM01 | M24: =G24 -> LRM
F25: =IFERROR(__xludf.DUMMYFUNCTION("""COMPUTED_VALUE"""),"Alberto Moreno") -> Alberto Moreno | G25: =IFERROR(__xludf.DUMMYFUNCTION("""COMPUTED_VALUE"""),"AMM") -> AMM | H25: =IFERROR(__xludf.DUMMYFUNCTION("""COMPUTED_VALUE"""),"AMM01") -> AMM01 | I25: =IFERROR(__xludf.DUMMYFUNCTION("""COMPUTED_VALUE"""),"A") -> A | J25: =IFERROR(__xludf.DUMMYFUNCTION("""COMPUTED_VALUE"""),"Adolfo del Valle Zapico") -> Adolfo del Valle Zapico | L25: =H25 -> AMM01 | M25: =G25 -> AMM
F26: =IFERROR(__xludf.DUMMYFUNCTION("""COMPUTED_VALUE"""),"Maika Blázquez") -> Maika Blázquez | G26: =IFERROR(__xludf.DUMMYFUNCTION("""COMPUTED_VALUE"""),"MBM") -> MBM | H26: =IFERROR(__xludf.DUMMYFUNCTION("""COMPUTED_VALUE"""),"MBM01") -> MBM01 | I26: =IFERROR(__xludf.DUMMYFUNCTION("""COMPUTED_VALUE"""),"A") -> A | J26: =IFERROR(__xludf.DUMMYFUNCTION("""COMPUTED_VALUE"""),"Adolfo Toledano Muñoz") -> Adolfo Toledano Muñoz | L26: =H26 -> MBM01 | M26: =G26 -> MBM
F27: =IFERROR(__xludf.DUMMYFUNCTION("""COMPUTED_VALUE"""),"Lisandro Russian") -> Lisandro Russian | G27: =IFERROR(__xludf.DUMMYFUNCTION("""COMPUTED_VALUE"""),"LRM") -> LRM | H27: =IFERROR(__xludf.DUMMYFUNCTION("""COMPUTED_VALUE"""),"LRM123") -> LRM123 | I27: =IFERROR(__xludf.DUMMYFUNCTION("""COMPUTED_VALUE"""),"A") -> A | J27: =IFERROR(__xludf.DUMMYFUNCTION("""COMPUTED_VALUE"""),"Adriana Pardo Maza") -> Adriana Pardo Maza | L27: =H27 -> LRM123 | M27: =G27 -> LRM
F28: =IFERROR(__xludf.DUMMYFUNCTION("""COMPUTED_VALUE"""),"Maika Blázquez") -> Maika Blázquez | G28: =IFERROR(__xludf.DUMMYFUNCTION("""COMPUTED_VALUE"""),"MBM") -> MBM | H28: =IFERROR(__xludf.DUMMYFUNCTION("""COMPUTED_VALUE"""),"MBM87") -> MBM87 | I28: =IFERROR(__xludf.DUMMYFUNCTION("""COMPUTED_VALUE"""),"A") -> A | J28: =IFERROR(__xludf.DUMMYFUNCTION("""COMPUTED_VALUE"""),"Adriana Pérez García") -> Adriana Pérez García | L28: =H28 -> MBM87 | M28: =G28 -> MBM
F29: =IFERROR(__xludf.DUMMYFUNCTION("""COMPUTED_VALUE"""),"Iván Sánchez") -> Iván Sánchez | G29: =IFERROR(__xludf.DUMMYFUNCTION("""COMPUTED_VALUE"""),"ISL") -> ISL | H29: =IFERROR(__xludf.DUMMYFUNCTION("""COMPUTED_VALUE"""),"ISL82") -> ISL82 | I29: =IFERROR(__xludf.DUMMYFUNCTION("""COMPUTED_VALUE"""),"B") -> B | J29: =IFERROR(__xludf.DUMMYFUNCTION("""COMPUTED_VALUE"""),"Africa Jiménez de la Rosa") -> Africa Jiménez de la Rosa | L29: =H29 -> ISL82 | M29: =G29 -> ISL
F30: =IFERROR(__xludf.DUMMYFUNCTION("""COMPUTED_VALUE"""),"Ramon Ferrando") -> Ramon Ferrando | G30: =IFERROR(__xludf.DUMMYFUNCTION("""COMPUTED_VALUE"""),"RFV") -> RFV | H30: =IFERROR(__xludf.DUMMYFUNCTION("""COMPUTED_VALUE"""),"RFV09") -> RFV09 | I30: =IFERROR(__xludf.DUMMYFUNCTION("""COMPUTED_VALUE"""),"B") -> B | J30: =IFERROR(__xludf.DUMMYFUNCTION("""COMPUTED_VALUE"""),"Agustín Campos Catalá") -> Agustín Campos Catalá | L30: =H30 -> RFV09 | M30: =G30 -> RFV
F31: =IFERROR(__xludf.DUMMYFUNCTION("""COMPUTED_VALUE"""),"Maika Blázquez") -> Maika Blázquez | G31: =IFERROR(__xludf.DUMMYFUNCTION("""COMPUTED_VALUE"""),"MBM") -> MBM | H31: =IFERROR(__xludf.DUMMYFUNCTION("""COMPUTED_VALUE"""),"MBM205") -> MBM205 | I31: =IFERROR(__xludf.DUMMYFUNCTION("""COMPUTED_VALUE"""),"A") -> A | J31: =IFERROR(__xludf.DUMMYFUNCTION("""COMPUTED_VALUE"""),"Agustina Nicole Arbia Kalutich") -> Agustina Nicole Arbia Kalutich | L31: =H31 -> MBM205 | M31: =G31 -> MBM
F32: =IFERROR(__xludf.DUMMYFUNCTION("""COMPUTED_VALUE"""),"Iván Sánchez") -> Iván Sánchez | G32: =IFERROR(__xludf.DUMMYFUNCTION("""COMPUTED_VALUE"""),"ISL") -> ISL | H32: =IFERROR(__xludf.DUMMYFUNCTION("""COMPUTED_VALUE"""),"ISL83") -> ISL83 | I32: =IFERROR(__xludf.DUMMYFUNCTION("""COMPUTED_VALUE"""),"B") -> B | J32: =IFERROR(__xludf.DUMMYFUNCTION("""COMPUTED_VALUE"""),"Aida Aviñoa Arias") -> Aida Aviñoa Arias | L32: =H32 -> ISL83 | M32: =G32 -> ISL
F33: =IFERROR(__xludf.DUMMYFUNCTION("""COMPUTED_VALUE"""),"Mercè Cabrera") -> Mercè Cabrera | G33: =IFERROR(__xludf.DUMMYFUNCTION("""COMPUTED_VALUE"""),"MCC") -> MCC | H33: =IFERROR(__xludf.DUMMYFUNCTION("""COMPUTED_VALUE"""),"MCC35") -> MCC35 | I33: =IFERROR(__xludf.DUMMYFUNCTION("""COMPUTED_VALUE"""),"A") -> A | J33: =IFERROR(__xludf.DUMMYFUNCTION("""COMPUTED_VALUE"""),"Aina Brunet García") -> Aina Brunet García | L33: =H33 -> MCC35 | M33: =G33 -> MCC
F34: =IFERROR(__xludf.DUMMYFUNCTION("""COMPUTED_VALUE"""),"Lisandro Russian") -> Lisandro Russian | G34: =IFERROR(__xludf.DUMMYFUNCTION("""COMPUTED_VALUE"""),"LRM") -> LRM | H34: =IFERROR(__xludf.DUMMYFUNCTION("""COMPUTED_VALUE"""),"LRM124") -> LRM124 | I34: =IFERROR(__xludf.DUMMYFUNCTION("""COMPUTED_VALUE"""),"A") -> A | J34: =IFERROR(__xludf.DUMMYFUNCTION("""COMPUTED_VALUE"""),"Ainhoa Beato Martínez") -> Ainhoa Beato Martínez | L34: =H34 -> LRM124 | M34: =G34 -> LRM
F35: =IFERROR(__xludf.DUMMYFUNCTION("""COMPUTED_VALUE"""),"Ramon Ferrando") -> Ramon Ferrando | G35: =IFERROR(__xludf.DUMMYFUNCTION("""COMPUTED_VALUE"""),"RFV") -> RFV | H35: =IFERROR(__xludf.DUMMYFUNCTION("""COMPUTED_VALUE"""),"RFV26") -> RFV26 | I35: =IFERROR(__xludf.DUMMYFUNCTION("""COMPUTED_VALUE"""),"B") -> B | J35: =IFERROR(__xludf.DUMMYFUNCTION("""COMPUTED_VALUE"""),"Ainhoa García-Lliberos de Miguel") -> Ainhoa García-Lliberos de Miguel | L35: =H35 -> RFV26 | M35: =G35 -> RFV
F36: =IFERROR(__xludf.DUMMYFUNCTION("""COMPUTED_VALUE"""),"Lisandro Russian") -> Lisandro Russian | G36: =IFERROR(__xludf.DUMMYFUNCTION("""COMPUTED_VALUE"""),"LRM") -> LRM | H36: =IFERROR(__xludf.DUMMYFUNCTION("""COMPUTED_VALUE"""),"LRM125") -> LRM125 | I36: =IFERROR(__xludf.DUMMYFUNCTION("""COMPUTED_VALUE"""),"A") -> A | J36: =IFERROR(__xludf.DUMMYFUNCTION("""COMPUTED_VALUE"""),"Ainhoa Moreno Bravo") -> Ainhoa Moreno Bravo | L36: =H36 -> LRM125 | M36: =G36 -> LRM
F37: =IFERROR(__xludf.DUMMYFUNCTION("""COMPUTED_VALUE"""),"Roberto Pereira") -> Roberto Pereira | G37: =IFERROR(__xludf.DUMMYFUNCTION("""COMPUTED_VALUE"""),"RPG") -> RPG | H37: =IFERROR(__xludf.DUMMYFUNCTION("""COMPUTED_VALUE"""),"RPG34") -> RPG34 | I37: =IFERROR(__xludf.DUMMYFUNCTION("""COMPUTED_VALUE"""),"A") -> A | J37: =IFERROR(__xludf.DUMMYFUNCTION("""COMPUTED_VALUE"""),"Alba Carrero González") -> Alba Carrero González | L37: =H37 -> RPG34 | M37: =G37 -> RPG
F38: =IFERROR(__xludf.DUMMYFUNCTION("""COMPUTED_VALUE"""),"Maika Blázquez") -> Maika Blázquez | G38: =IFERROR(__xludf.DUMMYFUNCTION("""COMPUTED_VALUE"""),"MBM") -> MBM | H38: =IFERROR(__xludf.DUMMYFUNCTION("""COMPUTED_VALUE"""),"MBM88") -> MBM88 | I38: =IFERROR(__xludf.DUMMYFUNCTION("""COMPUTED_VALUE"""),"A") -> A | J38: =IFERROR(__xludf.DUMMYFUNCTION("""COMPUTED_VALUE"""),"Alba Domínguez Palos") -> Alba Domínguez Palos | L38: =H38 -> MBM88 | M38: =G38 -> MBM
F39: =IFERROR(__xludf.DUMMYFUNCTION("""COMPUTED_VALUE"""),"Iván Sánchez") -> Iván Sánchez | G39: =IFERROR(__xludf.DUMMYFUNCTION("""COMPUTED_VALUE"""),"ISL") -> ISL | H39: =IFERROR(__xludf.DUMMYFUNCTION("""COMPUTED_VALUE"""),"ISL84") -> ISL84 | I39: =IFERROR(__xludf.DUMMYFUNCTION("""COMPUTED_VALUE"""),"B") -> B | J39: =IFERROR(__xludf.DUMMYFUNCTION("""COMPUTED_VALUE"""),"Alba Molina Moreno") -> Alba Molina Moreno | L39: =H39 -> ISL84 | M39: =G39 -> ISL
F40: =IFERROR(__xludf.DUMMYFUNCTION("""COMPUTED_VALUE"""),"Mercè Cabrera") -> Mercè Cabrera | G40: =IFERROR(__xludf.DUMMYFUNCTION("""COMPUTED_VALUE"""),"MCC") -> MCC | H40: =IFERROR(__xludf.DUMMYFUNCTION("""COMPUTED_VALUE"""),"MCC01") -> MCC01 | I40: =IFERROR(__xludf.DUMMYFUNCTION("""COMPUTED_VALUE"""),"A") -> A | J40: =IFERROR(__xludf.DUMMYFUNCTION("""COMPUTED_VALUE"""),"Albert Llansana Ríos") -> Albert Llansana Ríos | L40: =H40 -> MCC01 | M40: =G40 -> MCC
F41: =IFERROR(__xludf.DUMMYFUNCTION("""COMPUTED_VALUE"""),"Mercè Cabrera") -> Mercè Cabrera | G41: =IFERROR(__xludf.DUMMYFUNCTION("""COMPUTED_VALUE"""),"MCC") -> MCC | H41: =IFERROR(__xludf.DUMMYFUNCTION("""COMPUTED_VALUE"""),"MCC76") -> MCC76 | I41: =IFERROR(__xludf.DUMMYFUNCTION("""COMPUTED_VALUE"""),"A") -> A | J41: =IFERROR(__xludf.DUMMYFUNCTION("""COMPUTED_VALUE"""),"Albert Pla Esperanzi") -> Albert Pla Esperanzi | L41: =H41 -> MCC76 | M41: =G41 -> MCC
F42: =IFERROR(__xludf.DUMMYFUNCTION("""COMPUTED_VALUE"""),"Lisandro Russian") -> Lisandro Russian | G42: =IFERROR(__xludf.DUMMYFUNCTION("""COMPUTED_VALUE"""),"LRM") -> LRM | H42: =IFERROR(__xludf.DUMMYFUNCTION("""COMPUTED_VALUE"""),"LRM02") -> LRM02 | I42: =IFERROR(__xludf.DUMMYFUNCTION("""COMPUTED_VALUE"""),"A") -> A | J42: =IFERROR(__xludf.DUMMYFUNCTION("""COMPUTED_VALUE"""),"Alberto García Guzmán") -> Alberto García Guzmán | L42: =H42 -> LRM02 | M42: =G42 -> LRM
F43: =IFERROR(__xludf.DUMMYFUNCTION("""COMPUTED_VALUE"""),"Iván Sánchez") -> Iván Sánchez | G43: =IFERROR(__xludf.DUMMYFUNCTION("""COMPUTED_VALUE"""),"ISL") -> ISL | H43: =IFERROR(__xludf.DUMMYFUNCTION("""COMPUTED_VALUE"""),"ISL152") -> ISL152 | I43: =IFERROR(__xludf.DUMMYFUNCTION("""COMPUTED_VALUE"""),"B") -> B | J43: =IFERROR(__xludf.DUMMYFUNCTION("""COMPUTED_VALUE"""),"Alberto Guillén Martínez") -> Alberto Guillén Martínez | L43: =H43 -> ISL152 | M43: =G43 -> ISL
F44: =IFERROR(__xludf.DUMMYFUNCTION("""COMPUTED_VALUE"""),"Iván Sánchez") -> Iván Sánchez | G44: =IFERROR(__xludf.DUMMYFUNCTION("""COMPUTED_VALUE"""),"ISL") -> ISL | H44: =IFERROR(__xludf.DUMMYFUNCTION("""COMPUTED_VALUE"""),"ISL01") -> ISL01 | I44: =IFERROR(__xludf.DUMMYFUNCTION("""COMPUTED_VALUE"""),"B") -> B | J44: =IFERROR(__xludf.DUMMYFUNCTION("""COMPUTED_VALUE"""),"Alberto Raposo Jiménez") -> Alberto Raposo Jiménez | L44: =H44 -> ISL01 | M44: =G44 -> ISL
...

Sheet datos 2026
A1: ACTUALIZACIÓN A | B1: código visitador | C1: =IFERROR(__xludf.DUMMYFUNCTION("QUERY(IMPORTRANGE(""1y_3LleCxvzurbj_vKa53p6-h3HGan0CBvsIGq6qCvKU/edit?gid=1277712770#gid=1277712770"",""DATOSANALISIS!C:AM""),""SELECT Col1, Col4, Col5, Col6, Col7, Col8, Col9, Col13, Col14, Col15, Col16, Col18, Col19, Col21, Col29, Col35, Col36, Col37"","&"1)"),"cód ORL") -> cód ORL | D1: =IFERROR(__xludf.DUMMYFUNCTION("""COMPUTED_VALUE"""),"TIPO") -> TIPO | E1: =IFERROR(__xludf.DUMMYFUNCTION("""COMPUTED_VALUE"""),"Año Estado") -> Año Estado | F1: =IFERROR(__xludf.DUMMYFUNCTION("""COMPUTED_VALUE"""),"Mes Estado") -> Mes Estado | G1: =IFERROR(__xludf.DUMMYFUNCTION("""COMPUTED_VALUE"""),"SUCURSAL") -> SUCURSAL | H1: =IFERROR(__xludf.DUMMYFUNCTION("""COMPUTED_VALUE"""),"COD CLIENTE") -> COD CLIENTE | I1: =IFERROR(__xludf.DUMMYFUNCTION("""COMPUTED_VALUE"""),"NOMBRE CLIENTE") -> NOMBRE CLIENTE | J1: =IFERROR(__xludf.DUMMYFUNCTION("""COMPUTED_VALUE"""),"FECHA INICIO OPORTUNIDAD") -> FECHA INICIO OPORTUNIDAD | K1: =IFERROR(__xludf.DUMMYFUNCTION("""COMPUTED_VALUE"""),"ESTADO OPORTUNIDAD") -> ESTADO OPORTUNIDAD | L1: =IFERROR(__xludf.DUMMYFUNCTION("""COMPUTED_VALUE"""),"FECHA ESTADO OPORTUNIDAD") -> FECHA ESTADO OPORTUNIDAD | M1: =IFERROR(__xludf.DUMMYFUNCTION("""COMPUTED_VALUE"""),"RECOMPRA") -> RECOMPRA | N1: =IFERROR(__xludf.DUMMYFUNCTION("""COMPUTED_VALUE"""),"NUM AUDIFONOS") -> NUM AUDIFONOS | O1: =IFERROR(__xludf.DUMMYFUNCTION("""COMPUTED_VALUE"""),"MODELO (AUDIF 1)") -> MODELO (AUDIF 1) | P1: =IFERROR(__xludf.DUMMYFUNCTION("""COMPUTED_VALUE"""),"IMPORTE SIN IVA") -> IMPORTE SIN IVA | Q1: =IFERROR(__xludf.DUMMYFUNCTION("""COMPUTED_VALUE"""),"VISITADOR") -> VISITADOR | R1: =IFERROR(__xludf.DUMMYFUNCTION("""COMPUTED_VALUE"""),"NOMBRE ORL/CAMPAÑA") -> NOMBRE ORL/CAMPAÑA | S1: =IFERROR(__xludf.DUMMYFUNCTION("""COMPUTED_VALUE"""),"CANAL") -> CANAL | T1: =IFERROR(__xludf.DUMMYFUNCTION("""COMPUTED_VALUE"""),"SUBCANAL") -> SUBCANAL
A2: 46119 | B2: =IF($C2="","",LEFT(C2,3)) -> RFV | C2: =IFERROR(__xludf.DUMMYFUNCTION("""COMPUTED_VALUE"""),"RFV29") -> RFV29 | D2: =IFERROR(__xludf.DUMMYFUNCTION("""COMPUTED_VALUE"""),"PROPIOS") -> PROPIOS | E2: =IFERROR(__xludf.DUMMYFUNCTION("""COMPUTED_VALUE"""),2026) -> 2026 | F2: =IFERROR(__xludf.DUMMYFUNCTION("""COMPUTED_VALUE"""),1) -> 1 | G2: =IFERROR(__xludf.DUMMYFUNCTION("""COMPUTED_VALUE"""),"Valencia- Parra") -> Valencia- Parra | H2: =IFERROR(__xludf.DUMMYFUNCTION("""COMPUTED_VALUE"""),"C202511592157270489") -> C202511592157270489 | I2: =IFERROR(__xludf.DUMMYFUNCTION("""COMPUTED_VALUE"""),"HEINZ WIEST") -> HEINZ WIEST | J2: =IFERROR(__xludf.DUMMYFUNCTION("""COMPUTED_VALUE"""),45966) -> 45966 | K2: =IFERROR(__xludf.DUMMYFUNCTION("""COMPUTED_VALUE"""),"Factura audífonos") -> Factura audífonos | L2: =IFERROR(__xludf.DUMMYFUNCTION("""COMPUTED_VALUE"""),46024) -> 46024 | M2: =IFERROR(__xludf.DUMMYFUNCTION("""COMPUTED_VALUE"""),"NO") -> NO | N2: =IFERROR(__xludf.DUMMYFUNCTION("""COMPUTED_VALUE"""),2) -> 2 | O2: =IFERROR(__xludf.DUMMYFUNCTION("""COMPUTED_VALUE"""),"PRO") -> PRO | P2: =IFERROR(__xludf.DUMMYFUNCTION("""COMPUTED_VALUE"""),4536.36) -> 4536.36 | Q2: =IFERROR(__xludf.DUMMYFUNCTION("""COMPUTED_VALUE"""),"Ramon Ferrando") -> Ramon Ferrando | R2: =IFERROR(__xludf.DUMMYFUNCTION("""COMPUTED_VALUE"""),"Fe Rubio Escolano") -> Fe Rubio Escolano | S2: =IFERROR(__xludf.DUMMYFUNCTION("""COMPUTED_VALUE"""),"03 ORL") -> 03 ORL | T2: =IFERROR(__xludf.DUMMYFUNCTION("""COMPUTED_VALUE"""),"06 ORL") -> 06 ORL
B3: =IF($C3="","",LEFT(C3,3)) -> LRM | C3: =IFERROR(__xludf.DUMMYFUNCTION("""COMPUTED_VALUE"""),"LRM240") -> LRM240 | D3: =IFERROR(__xludf.DUMMYFUNCTION("""COMPUTED_VALUE"""),"ASOCIADOS") -> ASOCIADOS | E3: =IFERROR(__xludf.DUMMYFUNCTION("""COMPUTED_VALUE"""),2026) -> 2026 | F3: =IFERROR(__xludf.DUMMYFUNCTION("""COMPUTED_VALUE"""),1) -> 1 | G3: =IFERROR(__xludf.DUMMYFUNCTION("""COMPUTED_VALUE"""),"Cáceres") -> Cáceres | H3: =IFERROR(__xludf.DUMMYFUNCTION("""COMPUTED_VALUE"""),"C202512110551976531") -> C202512110551976531 | I3: =IFERROR(__xludf.DUMMYFUNCTION("""COMPUTED_VALUE"""),"JUAN MANUEL CORCHERO HIGUERO") -> JUAN MANUEL CORCHERO HIGUERO | J3: =IFERROR(__xludf.DUMMYFUNCTION("""COMPUTED_VALUE"""),45992) -> 45992 | K3: =IFERROR(__xludf.DUMMYFUNCTION("""COMPUTED_VALUE"""),"Factura audífonos") -> Factura audífonos | L3: =IFERROR(__xludf.DUMMYFUNCTION("""COMPUTED_VALUE"""),46024) -> 46024 | M3: =IFERROR(__xludf.DUMMYFUNCTION("""COMPUTED_VALUE"""),"NO") -> NO | N3: =IFERROR(__xludf.DUMMYFUNCTION("""COMPUTED_VALUE"""),2) -> 2 | O3: =IFERROR(__xludf.DUMMYFUNCTION("""COMPUTED_VALUE"""),"QUIET") -> QUIET | P3: =IFERROR(__xludf.DUMMYFUNCTION("""COMPUTED_VALUE"""),3636.36) -> 3636.36 | Q3: =IFERROR(__xludf.DUMMYFUNCTION("""COMPUTED_VALUE"""),"Lisandro Russian") -> Lisandro Russian | R3: =IFERROR(__xludf.DUMMYFUNCTION("""COMPUTED_VALUE"""),"Andrés Paulino Herrera") -> Andrés Paulino Herrera | S3: =IFERROR(__xludf.DUMMYFUNCTION("""COMPUTED_VALUE"""),"03 ORL") -> 03 ORL | T3: =IFERROR(__xludf.DUMMYFUNCTION("""COMPUTED_VALUE"""),"06 ORL") -> 06 ORL
B4: =IF($C4="","",LEFT(C4,3)) -> PSC | C4: =IFERROR(__xludf.DUMMYFUNCTION("""COMPUTED_VALUE"""),"PSC06") -> PSC06 | D4: =IFERROR(__xludf.DUMMYFUNCTION("""COMPUTED_VALUE"""),"ASOCIADOS") -> ASOCIADOS | E4: =IFERROR(__xludf.DUMMYFUNCTION("""COMPUTED_VALUE"""),2026) -> 2026 | F4: =IFERROR(__xludf.DUMMYFUNCTION("""COMPUTED_VALUE"""),1) -> 1 | G4: =IFERROR(__xludf.DUMMYFUNCTION("""COMPUTED_VALUE"""),"Valladolid") -> Valladolid | H4: =IFERROR(__xludf.DUMMYFUNCTION("""COMPUTED_VALUE"""),"VLL-474") -> VLL-474 | I4: =IFERROR(__xludf.DUMMYFUNCTION("""COMPUTED_VALUE"""),"GAUDENCIO GARCIA REGUERO") -> GAUDENCIO GARCIA REGUERO | J4: =IFERROR(__xludf.DUMMYFUNCTION("""COMPUTED_VALUE"""),45964) -> 45964 | K4: =IFERROR(__xludf.DUMMYFUNCTION("""COMPUTED_VALUE"""),"Factura audífonos") -> Factura audífonos | L4: =IFERROR(__xludf.DUMMYFUNCTION("""COMPUTED_VALUE"""),46027) -> 46027 | M4: =IFERROR(__xludf.DUMMYFUNCTION("""COMPUTED_VALUE"""),"NO") -> NO | N4: =IFERROR(__xludf.DUMMYFUNCTION("""COMPUTED_VALUE"""),2) -> 2 | O4: =IFERROR(__xludf.DUMMYFUNCTION("""COMPUTED_VALUE"""),"CONFORT") -> CONFORT | P4: =IFERROR(__xludf.DUMMYFUNCTION("""COMPUTED_VALUE"""),3522.73) -> 3522.73 | Q4: =IFERROR(__xludf.DUMMYFUNCTION("""COMPUTED_VALUE"""),"Alberto Moreno") -> Alberto Moreno | R4: =IFERROR(__xludf.DUMMYFUNCTION("""COMPUTED_VALUE"""),"Carlos Miguel Salvador Martínez") -> Carlos Miguel Salvador Martínez | S4: =IFERROR(__xludf.DUMMYFUNCTION("""COMPUTED_VALUE"""),"03 ORL") -> 03 ORL | T4: =IFERROR(__xludf.DUMMYFUNCTION("""COMPUTED_VALUE"""),"06 ORL") -> 06 ORL
B5: =IF($C5="","",LEFT(C5,3)) -> MBM | C5: =IFERROR(__xludf.DUMMYFUNCTION("""COMPUTED_VALUE"""),"MBM156") -> MBM156 | D5: =IFERROR(__xludf.DUMMYFUNCTION("""COMPUTED_VALUE"""),"PROPIOS") -> PROPIOS | E5: =IFERROR(__xludf.DUMMYFUNCTION("""COMPUTED_VALUE"""),2026) -> 2026 | F5: =IFERROR(__xludf.DUMMYFUNCTION("""COMPUTED_VALUE"""),1) -> 1 | G5: =IFERROR(__xludf.DUMMYFUNCTION("""COMPUTED_VALUE"""),"Getafe") -> Getafe | H5: =IFERROR(__xludf.DUMMYFUNCTION("""COMPUTED_VALUE"""),"C202511141135536493") -> C202511141135536493 | I5: =IFERROR(__xludf.DUMMYFUNCTION("""COMPUTED_VALUE"""),"ANTONIO CALVETE OLIVA") -> ANTONIO CALVETE OLIVA | J5: =IFERROR(__xludf.DUMMYFUNCTION("""COMPUTED_VALUE"""),45975) -> 45975 | K5: =IFERROR(__xludf.DUMMYFUNCTION("""COMPUTED_VALUE"""),"Factura audífonos") -> Factura audífonos | L5: =IFERROR(__xludf.DUMMYFUNCTION("""COMPUTED_VALUE"""),46027) -> 46027 | M5: =IFERROR(__xludf.DUMMYFUNCTION("""COMPUTED_VALUE"""),"NO") -> NO | N5: =IFERROR(__xludf.DUMMYFUNCTION("""COMPUTED_VALUE"""),1) -> 1 | O5: =IFERROR(__xludf.DUMMYFUNCTION("""COMPUTED_VALUE"""),"CONFORT") -> CONFORT | P5: =IFERROR(__xludf.DUMMYFUNCTION("""COMPUTED_VALUE"""),2180.91) -> 2180.91 | Q5: =IFERROR(__xludf.DUMMYFUNCTION("""COMPUTED_VALUE"""),"Maika Blázquez") -> Maika Blázquez | R5: =IFERROR(__xludf.DUMMYFUNCTION("""COMPUTED_VALUE"""),"Marta Colmenero Ruiz") -> Marta Colmenero Ruiz | S5: =IFERROR(__xludf.DUMMYFUNCTION("""COMPUTED_VALUE"""),"03 ORL") -> 03 ORL | T5: =IFERROR(__xludf.DUMMYFUNCTION("""COMPUTED_VALUE"""),"06 ORL") -> 06 ORL
B6: =IF($C6="","",LEFT(C6,3)) -> MBM | C6: =IFERROR(__xludf.DUMMYFUNCTION("""COMPUTED_VALUE"""),"MBM07") -> MBM07 | D6: =IFERROR(__xludf.DUMMYFUNCTION("""COMPUTED_VALUE"""),"PARTICIPADOS") -> PARTICIPADOS | E6: =IFERROR(__xludf.DUMMYFUNCTION("""COMPUTED_VALUE"""),2026) -> 2026 | F6: =IFERROR(__xludf.DUMMYFUNCTION("""COMPUTED_VALUE"""),1) -> 1 | G6: =IFERROR(__xludf.DUMMYFUNCTION("""COMPUTED_VALUE"""),"Madrid- La Oca") -> Madrid- La Oca | H6: =IFERROR(__xludf.DUMMYFUNCTION("""COMPUTED_VALUE"""),"C202511171016459133") -> C202511171016459133 | I6: =IFERROR(__xludf.DUMMYFUNCTION("""COMPUTED_VALUE"""),"AMELIA DIAZ VAZQUEZ") -> AMELIA DIAZ VAZQUEZ | J6: =IFERROR(__xludf.DUMMYFUNCTION("""COMPUTED_VALUE"""),45978) -> 45978 | K6: =IFERROR(__xludf.DUMMYFUNCTION("""COMPUTED_VALUE"""),"Factura audífonos") -> Factura audífonos | L6: =IFERROR(__xludf.DUMMYFUNCTION("""COMPUTED_VALUE"""),46029) -> 46029 | M6: =IFERROR(__xludf.DUMMYFUNCTION("""COMPUTED_VALUE"""),"NO") -> NO | N6: =IFERROR(__xludf.DUMMYFUNCTION("""COMPUTED_VALUE"""),2) -> 2 | O6: =IFERROR(__xludf.DUMMYFUNCTION("""COMPUTED_VALUE"""),"QUIET") -> QUIET | P6: =IFERROR(__xludf.DUMMYFUNCTION("""COMPUTED_VALUE"""),2718.18) -> 2718.18 | Q6: =IFERROR(__xludf.DUMMYFUNCTION("""COMPUTED_VALUE"""),"Maika Blázquez") -> Maika Blázquez | R6: =IFERROR(__xludf.DUMMYFUNCTION("""COMPUTED_VALUE"""),"Andreas Schilling Borghesi") -> Andreas Schilling Borghesi | S6: =IFERROR(__xludf.DUMMYFUNCTION("""COMPUTED_VALUE"""),"03 ORL") -> 03 ORL | T6: =IFERROR(__xludf.DUMMYFUNCTION("""COMPUTED_VALUE"""),"06 ORL") -> 06 ORL
B7: =IF($C7="","",LEFT(C7,3)) -> MBM | C7: =IFERROR(__xludf.DUMMYFUNCTION("""COMPUTED_VALUE"""),"MBM52") -> MBM52 | D7: =IFERROR(__xludf.DUMMYFUNCTION("""COMPUTED_VALUE"""),"PARTICIPADOS") -> PARTICIPADOS | E7: =IFERROR(__xludf.DUMMYFUNCTION("""COMPUTED_VALUE"""),2026) -> 2026 | F7: =IFERROR(__xludf.DUMMYFUNCTION("""COMPUTED_VALUE"""),1) -> 1 | G7: =IFERROR(__xludf.DUMMYFUNCTION("""COMPUTED_VALUE"""),"Madrid- La Oca") -> Madrid- La Oca | H7: =IFERROR(__xludf.DUMMYFUNCTION("""COMPUTED_VALUE"""),"C202512911304031492") -> C202512911304031492 | I7: =IFERROR(__xludf.DUMMYFUNCTION("""COMPUTED_VALUE"""),"REMEDIOS VECINO PRIETO") -> REMEDIOS VECINO PRIETO | J7: =IFERROR(__xludf.DUMMYFUNCTION("""COMPUTED_VALUE"""),46000) -> 46000 | K7: =IFERROR(__xludf.DUMMYFUNCTION("""COMPUTED_VALUE"""),"Factura audífonos") -> Factura audífonos | L7: =IFERROR(__xludf.DUMMYFUNCTION("""COMPUTED_VALUE"""),46030) -> 46030 | M7: =IFERROR(__xludf.DUMMYFUNCTION("""COMPUTED_VALUE"""),"NO") -> NO | N7: =IFERROR(__xludf.DUMMYFUNCTION("""COMPUTED_VALUE"""),2) -> 2 | O7: =IFERROR(__xludf.DUMMYFUNCTION("""COMPUTED_VALUE"""),"QUIET") -> QUIET | P7: =IFERROR(__xludf.DUMMYFUNCTION("""COMPUTED_VALUE"""),2718.18) -> 2718.18 | Q7: =IFERROR(__xludf.DUMMYFUNCTION("""COMPUTED_VALUE"""),"Maika Blázquez") -> Maika Blázquez | R7: =IFERROR(__xludf.DUMMYFUNCTION("""COMPUTED_VALUE"""),"José Joaquín Gutiérrez Barquín") -> José Joaquín Gutiérrez Barquín | S7: =IFERROR(__xludf.DUMMYFUNCTION("""COMPUTED_VALUE"""),"03 ORL") -> 03 ORL | T7: =IFERROR(__xludf.DUMMYFUNCTION("""COMPUTED_VALUE"""),"06 ORL") -> 06 ORL
B8: =IF($C8="","",LEFT(C8,3)) | D8: =IFERROR(__xludf.DUMMYFUNCTION("""COMPUTED_VALUE"""),"ASOCIADOS") -> ASOCIADOS | E8: =IFERROR(__xludf.DUMMYFUNCTION("""COMPUTED_VALUE"""),2026) -> 2026 | F8: =IFERROR(__xludf.DUMMYFUNCTION("""COMPUTED_VALUE"""),1) -> 1 | G8: =IFERROR(__xludf.DUMMYFUNCTION("""COMPUTED_VALUE"""),"Sevilla- Ciencias") -> Sevilla- Ciencias | H8: =IFERROR(__xludf.DUMMYFUNCTION("""COMPUTED_VALUE"""),"C202511201556282288") -> C202511201556282288 | I8: =IFERROR(__xludf.DUMMYFUNCTION("""COMPUTED_VALUE"""),"CONCEPCION ORTIZ SANTIAGO") -> CONCEPCION ORTIZ SANTIAGO | J8: =IFERROR(__xludf.DUMMYFUNCTION("""COMPUTED_VALUE"""),45981) -> 45981 | K8: =IFERROR(__xludf.DUMMYFUNCTION("""COMPUTED_VALUE"""),"Factura audífonos") -> Factura audífonos | L8: =IFERROR(__xludf.DUMMYFUNCTION("""COMPUTED_VALUE"""),46030) -> 46030 | M8: =IFERROR(__xludf.DUMMYFUNCTION("""COMPUTED_VALUE"""),"NO") -> NO | N8: =IFERROR(__xludf.DUMMYFUNCTION("""COMPUTED_VALUE"""),2) -> 2 | O8: =IFERROR(__xludf.DUMMYFUNCTION("""COMPUTED_VALUE"""),"ADVANCED") -> ADVANCED | P8: =IFERROR(__xludf.DUMMYFUNCTION("""COMPUTED_VALUE"""),4120) -> 4120 | Q8: =IFERROR(__xludf.DUMMYFUNCTION("""COMPUTED_VALUE"""),"Luis Alberto Rodríguez") -> Luis Alberto Rodríguez | R8: =IFERROR(__xludf.DUMMYFUNCTION("""COMPUTED_VALUE"""),"No recuerda ORL") -> No recuerda ORL | S8: =IFERROR(__xludf.DUMMYFUNCTION("""COMPUTED_VALUE"""),"03 ORL") -> 03 ORL | T8: =IFERROR(__xludf.DUMMYFUNCTION("""COMPUTED_VALUE"""),"06 ORL") -> 06 ORL
B9: =IF($C9="","",LEFT(C9,3)) -> MBM | C9: =IFERROR(__xludf.DUMMYFUNCTION("""COMPUTED_VALUE"""),"MBM156") -> MBM156 | D9: =IFERROR(__xludf.DUMMYFUNCTION("""COMPUTED_VALUE"""),"PROPIOS") -> PROPIOS | E9: =IFERROR(__xludf.DUMMYFUNCTION("""COMPUTED_VALUE"""),2026) -> 2026 | F9: =IFERROR(__xludf.DUMMYFUNCTION("""COMPUTED_VALUE"""),1) -> 1 | G9: =IFERROR(__xludf.DUMMYFUNCTION("""COMPUTED_VALUE"""),"Getafe") -> Getafe | H9: =IFERROR(__xludf.DUMMYFUNCTION("""COMPUTED_VALUE"""),"C202511271003718318") -> C202511271003718318 | I9: =IFERROR(__xludf.DUMMYFUNCTION("""COMPUTED_VALUE"""),"MARIA ROSA ALONSO GONZÁLEZ") -> MARIA ROSA ALONSO GONZÁLEZ | J9: =IFERROR(__xludf.DUMMYFUNCTION("""COMPUTED_VALUE"""),45988) -> 45988 | K9: =IFERROR(__xludf.DUMMYFUNCTION("""COMPUTED_VALUE"""),"Factura audífonos") -> Factura audífonos | L9: =IFERROR(__xludf.DUMMYFUNCTION("""COMPUTED_VALUE"""),46030) -> 46030 | M9: =IFERROR(__xludf.DUMMYFUNCTION("""COMPUTED_VALUE"""),"NO") -> NO | N9: =IFERROR(__xludf.DUMMYFUNCTION("""COMPUTED_VALUE"""),2) -> 2 | O9: =IFERROR(__xludf.DUMMYFUNCTION("""COMPUTED_VALUE"""),"ADVANCED") -> ADVANCED | P9: =IFERROR(__xludf.DUMMYFUNCTION("""COMPUTED_VALUE"""),4136.36) -> 4136.36 | Q9: =IFERROR(__xludf.DUMMYFUNCTION("""COMPUTED_VALUE"""),"Maika Blázquez") -> Maika Blázquez | R9: =IFERROR(__xludf.DUMMYFUNCTION("""COMPUTED_VALUE"""),"Marta Colmenero Ruiz") -> Marta Colmenero Ruiz | S9: =IFERROR(__xludf.DUMMYFUNCTION("""COMPUTED_VALUE"""),"03 ORL") -> 03 ORL | T9: =IFERROR(__xludf.DUMMYFUNCTION("""COMPUTED_VALUE"""),"06 ORL") -> 06 ORL
B10: =IF($C10="","",LEFT(C10,3)) -> MBM | C10: =IFERROR(__xludf.DUMMYFUNCTION("""COMPUTED_VALUE"""),"MBM45") -> MBM45 | D10: =IFERROR(__xludf.DUMMYFUNCTION("""COMPUTED_VALUE"""),"PROPIOS") -> PROPIOS | E10: =IFERROR(__xludf.DUMMYFUNCTION("""COMPUTED_VALUE"""),2026) -> 2026 | F10: =IFERROR(__xludf.DUMMYFUNCTION("""COMPUTED_VALUE"""),1) -> 1 | G10: =IFERROR(__xludf.DUMMYFUNCTION("""COMPUTED_VALUE"""),"Madrid- Juan Bravo") -> Madrid- Juan Bravo | H10: =IFERROR(__xludf.DUMMYFUNCTION("""COMPUTED_VALUE"""),"JBR-1800") -> JBR-1800 | I10: =IFERROR(__xludf.DUMMYFUNCTION("""COMPUTED_VALUE"""),"JOSE LUIS RODRIGUEZ SIERRA") -> JOSE LUIS RODRIGUEZ SIERRA | J10: =IFERROR(__xludf.DUMMYFUNCTION("""COMPUTED_VALUE"""),45058) -> 45058 | K10: =IFERROR(__xludf.DUMMYFUNCTION("""COMPUTED_VALUE"""),"Factura audífonos") -> Factura audífonos | L10: =IFERROR(__xludf.DUMMYFUNCTION("""COMPUTED_VALUE"""),46030) -> 46030 | M10: =IFERROR(__xludf.DUMMYFUNCTION("""COMPUTED_VALUE"""),"SI") -> SI | N10: =IFERROR(__xludf.DUMMYFUNCTION("""COMPUTED_VALUE"""),1) -> 1 | O10: =IFERROR(__xludf.DUMMYFUNCTION("""COMPUTED_VALUE"""),"QUIET") -> QUIET | P10: =IFERROR(__xludf.DUMMYFUNCTION("""COMPUTED_VALUE"""),1543.52) -> 1543.52 | Q10: =IFERROR(__xludf.DUMMYFUNCTION("""COMPUTED_VALUE"""),"Maika Blázquez") -> Maika Blázquez | R10: =IFERROR(__xludf.DUMMYFUNCTION("""COMPUTED_VALUE"""),"Joaquín Alacio Casero") -> Joaquín Alacio Casero | S10: =IFERROR(__xludf.DUMMYFUNCTION("""COMPUTED_VALUE"""),"04 TIENDA") -> 04 TIENDA | T10: =IFERROR(__xludf.DUMMYFUNCTION("""COMPUTED_VALUE"""),"10 REVISIÓN POST-VENTA") -> 10 REVISIÓN POST-VENTA
B11: =IF($C11="","",LEFT(C11,3)) -> MBM | C11: =IFERROR(__xludf.DUMMYFUNCTION("""COMPUTED_VALUE"""),"MBM45") -> MBM45 | D11: =IFERROR(__xludf.DUMMYFUNCTION("""COMPUTED_VALUE"""),"PARTICIPADOS") -> PARTICIPADOS | E11: =IFERROR(__xludf.DUMMYFUNCTION("""COMPUTED_VALUE"""),2026) -> 2026 | F11: =IFERROR(__xludf.DUMMYFUNCTION("""COMPUTED_VALUE"""),1) -> 1 | G11: =IFERROR(__xludf.DUMMYFUNCTION("""COMPUTED_VALUE"""),"Madrid- La Oca") -> Madrid- La Oca | H11: =IFERROR(__xludf.DUMMYFUNCTION("""COMPUTED_VALUE"""),"C202511241158254265") -> C202511241158254265 | I11: =IFERROR(__xludf.DUMMYFUNCTION("""COMPUTED_VALUE"""),"MARIA DEL CARMEN GARCIA ROYO") -> MARIA DEL CARMEN GARCIA ROYO | J11: =IFERROR(__xludf.DUMMYFUNCTION("""COMPUTED_VALUE"""),45985) -> 45985 | K11: =IFERROR(__xludf.DUMMYFUNCTION("""COMPUTED_VALUE"""),"Factura audífonos") -> Factura audífonos | L11: =IFERROR(__xludf.DUMMYFUNCTION("""COMPUTED_VALUE"""),46031) -> 46031 | M11: =IFERROR(__xludf.DUMMYFUNCTION("""COMPUTED_VALUE"""),"NO") -> NO | N11: =IFERROR(__xludf.DUMMYFUNCTION("""COMPUTED_VALUE"""),2) -> 2 | O11: =IFERROR(__xludf.DUMMYFUNCTION("""COMPUTED_VALUE"""),"CONFORT") -> CONFORT | P11: =IFERROR(__xludf.DUMMYFUNCTION("""COMPUTED_VALUE"""),3631.82) -> 3631.82 | Q11: =IFERROR(__xludf.DUMMYFUNCTION("""COMPUTED_VALUE"""),"Maika Blázquez") -> Maika Blázquez | R11: =IFERROR(__xludf.DUMMYFUNCTION("""COMPUTED_VALUE"""),"Joaquín Alacio Casero") -> Joaquín Alacio Casero | S11: =IFERROR(__xludf.DUMMYFUNCTION("""COMPUTED_VALUE"""),"03 ORL") -> 03 ORL | T11: =IFERROR(__xludf.DUMMYFUNCTION("""COMPUTED_VALUE"""),"06 ORL") -> 06 ORL
B12: =IF($C12="","",LEFT(C12,3)) -> LRM | C12: =IFERROR(__xludf.DUMMYFUNCTION("""COMPUTED_VALUE"""),"LRM56") -> LRM56 | D12: =IFERROR(__xludf.DUMMYFUNCTION("""COMPUTED_VALUE"""),"ASOCIADOS") -> ASOCIADOS | E12: =IFERROR(__xludf.DUMMYFUNCTION("""COMPUTED_VALUE"""),2026) -> 2026 | F12: =IFERROR(__xludf.DUMMYFUNCTION("""COMPUTED_VALUE"""),1) -> 1 | G12: =IFERROR(__xludf.DUMMYFUNCTION("""COMPUTED_VALUE"""),"Zaragoza- León XIII") -> Zaragoza- León XIII | H12: =IFERROR(__xludf.DUMMYFUNCTION("""COMPUTED_VALUE"""),"C202510711221228") -> C202510711221228 | I12: =IFERROR(__xludf.DUMMYFUNCTION("""COMPUTED_VALUE"""),"MIGUEL ÁNGEL GASCA SANCHO") -> MIGUEL ÁNGEL GASCA SANCHO | J12: =IFERROR(__xludf.DUMMYFUNCTION("""COMPUTED_VALUE"""),45932) -> 45932 | K12: =IFERROR(__xludf.DUMMYFUNCTION("""COMPUTED_VALUE"""),"Factura audífonos") -> Factura audífonos | L12: =IFERROR(__xludf.DUMMYFUNCTION("""COMPUTED_VALUE"""),46031) -> 46031 | M12: =IFERROR(__xludf.DUMMYFUNCTION("""COMPUTED_VALUE"""),"NO") -> NO | N12: =IFERROR(__xludf.DUMMYFUNCTION("""COMPUTED_VALUE"""),2) -> 2 | O12: =IFERROR(__xludf.DUMMYFUNCTION("""COMPUTED_VALUE"""),"CONFORT") -> CONFORT | P12: =IFERROR(__xludf.DUMMYFUNCTION("""COMPUTED_VALUE"""),3424.55) -> 3424.55 | Q12: =IFERROR(__xludf.DUMMYFUNCTION("""COMPUTED_VALUE"""),"Mercè Cabrera") -> Mercè Cabrera | R12: =IFERROR(__xludf.DUMMYFUNCTION("""COMPUTED_VALUE"""),"Jaime Leache Pueyo") -> Jaime Leache Pueyo | S12: =IFERROR(__xludf.DUMMYFUNCTION("""COMPUTED_VALUE"""),"03 ORL") -> 03 ORL | T12: =IFERROR(__xludf.DUMMYFUNCTION("""COMPUTED_VALUE"""),"06 ORL") -> 06 ORL
B13: =IF($C13="","",LEFT(C13,3)) -> MBM | C13: =IFERROR(__xludf.DUMMYFUNCTION("""COMPUTED_VALUE"""),"MBM113") -> MBM113 | D13: =IFERROR(__xludf.DUMMYFUNCTION("""COMPUTED_VALUE"""),"PROPIOS") -> PROPIOS | E13: =IFERROR(__xludf.DUMMYFUNCTION("""COMPUTED_VALUE"""),2026) -> 2026 | F13: =IFERROR(__xludf.DUMMYFUNCTION("""COMPUTED_VALUE"""),1) -> 1 | G13: =IFERROR(__xludf.DUMMYFUNCTION("""COMPUTED_VALUE"""),"Fuenlabrada") -> Fuenlabrada | H13: =IFERROR(__xludf.DUMMYFUNCTION("""COMPUTED_VALUE"""),"C202512151217324826") -> C202512151217324826 | I13: =IFERROR(__xludf.DUMMYFUNCTION("""COMPUTED_VALUE"""),"Mª CARMEN DELGADO ANTON") -> Mª CARMEN DELGADO ANTON | J13: =IFERROR(__xludf.DUMMYFUNCTION("""COMPUTED_VALUE"""),46006) -> 46006 | K13: =IFERROR(__xludf.DUMMYFUNCTION("""COMPUTED_VALUE"""),"Factura audífonos") -> Factura audífonos | L13: =IFERROR(__xludf.DUMMYFUNCTION("""COMPUTED_VALUE"""),46031) -> 46031 | M13: =IFERROR(__xludf.DUMMYFUNCTION("""COMPUTED_VALUE"""),"NO") -> NO | N13: =IFERROR(__xludf.DUMMYFUNCTION("""COMPUTED_VALUE"""),1) -> 1 | O13: =IFERROR(__xludf.DUMMYFUNCTION("""COMPUTED_VALUE"""),"CONFORT") -> CONFORT | P13: =IFERROR(__xludf.DUMMYFUNCTION("""COMPUTED_VALUE"""),2180.91) -> 2180.91 | Q13: =IFERROR(__xludf.DUMMYFUNCTION("""COMPUTED_VALUE"""),"Maika Blázquez") -> Maika Blázquez | R13: =IFERROR(__xludf.DUMMYFUNCTION("""COMPUTED_VALUE"""),"Estefania Miranda Sánchez") -> Estefania Miranda Sánchez | S13: =IFERROR(__xludf.DUMMYFUNCTION("""COMPUTED_VALUE"""),"03 ORL") -> 03 ORL | T13: =IFERROR(__xludf.DUMMYFUNCTION("""COMPUTED_VALUE"""),"06 ORL") -> 06 ORL
B14: =IF($C14="","",LEFT(C14,3)) -> LAA | C14: =IFERROR(__xludf.DUMMYFUNCTION("""COMPUTED_VALUE"""),"LAA54") -> LAA54 | D14: =IFERROR(__xludf.DUMMYFUNCTION("""COMPUTED_VALUE"""),"PROPIOS") -> PROPIOS | E14: =IFERROR(__xludf.DUMMYFUNCTION("""COMPUTED_VALUE"""),2026) -> 2026 | F14: =IFERROR(__xludf.DUMMYFUNCTION("""COMPUTED_VALUE"""),1) -> 1 | G14: =IFERROR(__xludf.DUMMYFUNCTION("""COMPUTED_VALUE"""),"Sevilla- Montoto") -> Sevilla- Montoto | H14: =IFERROR(__xludf.DUMMYFUNCTION("""COMPUTED_VALUE"""),"C2024112910652762") -> C2024112910652762 | I14: =IFERROR(__xludf.DUMMYFUNCTION("""COMPUTED_VALUE"""),"SONIA SUAREZ FERNANDEZ") -> SONIA SUAREZ FERNANDEZ | J14: =IFERROR(__xludf.DUMMYFUNCTION("""COMPUTED_VALUE"""),45623) -> 45623 | K14: =IFERROR(__xludf.DUMMYFUNCTION("""COMPUTED_VALUE"""),"Factura audífonos") -> Factura audífonos | L14: =IFERROR(__xludf.DUMMYFUNCTION("""COMPUTED_VALUE"""),46034) -> 46034 | M14: =IFERROR(__xludf.DUMMYFUNCTION("""COMPUTED_VALUE"""),"NO") -> NO | N14: =IFERROR(__xludf.DUMMYFUNCTION("""COMPUTED_VALUE"""),1) -> 1 | O14: =IFERROR(__xludf.DUMMYFUNCTION("""COMPUTED_VALUE"""),"CONFORT") -> CONFORT | P14: =IFERROR(__xludf.DUMMYFUNCTION("""COMPUTED_VALUE"""),2072.73) -> 2072.73 | Q14: =IFERROR(__xludf.DUMMYFUNCTION("""COMPUTED_VALUE"""),"Luis Alberto Rodríguez") -> Luis Alberto Rodríguez | R14: =IFERROR(__xludf.DUMMYFUNCTION("""COMPUTED_VALUE"""),"María Luisa Calero Ramos") -> María Luisa Calero Ramos | S14: =IFERROR(__xludf.DUMMYFUNCTION("""COMPUTED_VALUE"""),"03 ORL") -> 03 ORL | T14: =IFERROR(__xludf.DUMMYFUNCTION("""COMPUTED_VALUE"""),"06 ORL") -> 06 ORL
B15: =IF($C15="","",LEFT(C15,3)) -> ISL | C15: =IFERROR(__xludf.DUMMYFUNCTION("""COMPUTED_VALUE"""),"ISL99") -> ISL99 | D15: =IFERROR(__xludf.DUMMYFUNCTION("""COMPUTED_VALUE"""),"PROPIOS") -> PROPIOS | E15: =IFERROR(__xludf.DUMMYFUNCTION("""COMPUTED_VALUE"""),2026) -> 2026 | F15: =IFERROR(__xludf.DUMMYFUNCTION("""COMPUTED_VALUE"""),1) -> 1 | G15: =IFERROR(__xludf.DUMMYFUNCTION("""COMPUTED_VALUE"""),"Alicante") -> Alicante | H15: =IFERROR(__xludf.DUMMYFUNCTION("""COMPUTED_VALUE"""),"C202512158433763329") -> C202512158433763329 | I15: =IFERROR(__xludf.DUMMYFUNCTION("""COMPUTED_VALUE"""),"TERESA VENTURA RODRIGUEZ") -> TERESA VENTURA RODRIGUEZ | J15: =IFERROR(__xludf.DUMMYFUNCTION("""COMPUTED_VALUE"""),46006) -> 46006 | K15: =IFERROR(__xludf.DUMMYFUNCTION("""COMPUTED_VALUE"""),"Factura audífonos") -> Factura audífonos | L15: =IFERROR(__xludf.DUMMYFUNCTION("""COMPUTED_VALUE"""),46034) -> 46034 | M15: =IFERROR(__xludf.DUMMYFUNCTION("""COMPUTED_VALUE"""),"NO") -> NO | N15: =IFERROR(__xludf.DUMMYFUNCTION("""COMPUTED_VALUE"""),2) -> 2 | O15: =IFERROR(__xludf.DUMMYFUNCTION("""COMPUTED_VALUE"""),"QUIET") -> QUIET | P15: =IFERROR(__xludf.DUMMYFUNCTION("""COMPUTED_VALUE"""),2718.18) -> 2718.18 | Q15: =IFERROR(__xludf.DUMMYFUNCTION("""COMPUTED_VALUE"""),"Iván Sánchez") -> Iván Sánchez | R15: =IFERROR(__xludf.DUMMYFUNCTION("""COMPUTED_VALUE"""),"Cristina Muñoz Pinto") -> Cristina Muñoz Pinto | S15: =IFERROR(__xludf.DUMMYFUNCTION("""COMPUTED_VALUE"""),"03 ORL") -> 03 ORL | T15: =IFERROR(__xludf.DUMMYFUNCTION("""COMPUTED_VALUE"""),"06 ORL") -> 06 ORL
B16: =IF($C16="","",LEFT(C16,3)) -> MBM | C16: =IFERROR(__xludf.DUMMYFUNCTION("""COMPUTED_VALUE"""),"MBM219") -> MBM219 | D16: =IFERROR(__xludf.DUMMYFUNCTION("""COMPUTED_VALUE"""),"PROPIOS") -> PROPIOS | E16: =IFERROR(__xludf.DUMMYFUNCTION("""COMPUTED_VALUE"""),2026) -> 2026 | F16: =IFERROR(__xludf.DUMMYFUNCTION("""COMPUTED_VALUE"""),1) -> 1 | G16: =IFERROR(__xludf.DUMMYFUNCTION("""COMPUTED_VALUE"""),"Getafe") -> Getafe | H16: =IFERROR(__xludf.DUMMYFUNCTION("""COMPUTED_VALUE"""),"C202511594452200485") -> C202511594452200485 | I16: =IFERROR(__xludf.DUMMYFUNCTION("""COMPUTED_VALUE"""),"JUAN JESÚS MAYA TORREJÓN") -> JUAN JESÚS MAYA TORREJÓN | J16: =IFERROR(__xludf.DUMMYFUNCTION("""COMPUTED_VALUE"""),45966) -> 45966 | K16: =IFERROR(__xludf.DUMMYFUNCTION("""COMPUTED_VALUE"""),"Factura audífonos") -> Factura audífonos | L16: =IFERROR(__xludf.DUMMYFUNCTION("""COMPUTED_VALUE"""),46034) -> 46034 | M16: =IFERROR(__xludf.DUMMYFUNCTION("""COMPUTED_VALUE"""),"NO") -> NO | N16: =IFERROR(__xludf.DUMMYFUNCTION("""COMPUTED_VALUE"""),1) -> 1 | O16: =IFERROR(__xludf.DUMMYFUNCTION("""COMPUTED_VALUE"""),"ADVANCED") -> ADVANCED | P16: =IFERROR(__xludf.DUMMYFUNCTION("""COMPUTED_VALUE"""),2481.82) -> 2481.82 | Q16: =IFERROR(__xludf.DUMMYFUNCTION("""COMPUTED_VALUE"""),"Maika Blázquez") -> Maika Blázquez | R16: =IFERROR(__xludf.DUMMYFUNCTION("""COMPUTED_VALUE"""),"Paula Morales Chacchi") -> Paula Morales Chacchi | S16: =IFERROR(__xludf.DUMMYFUNCTION("""COMPUTED_VALUE"""),"03 ORL") -> 03 ORL | T16: =IFERROR(__xludf.DUMMYFUNCTION("""COMPUTED_VALUE"""),"06 ORL") -> 06 ORL
B17: =IF($C17="","",LEFT(C17,3)) -> LRM | C17: =IFERROR(__xludf.DUMMYFUNCTION("""COMPUTED_VALUE"""),"LRM253") -> LRM253 | D17: =IFERROR(__xludf.DUMMYFUNCTION("""COMPUTED_VALUE"""),"ASOCIADOS") -> ASOCIADOS | E17: =IFERROR(__xludf.DUMMYFUNCTION("""COMPUTED_VALUE"""),2026) -> 2026 | F17: =IFERROR(__xludf.DUMMYFUNCTION("""COMPUTED_VALUE"""),1) -> 1 | G17: =IFERROR(__xludf.DUMMYFUNCTION("""COMPUTED_VALUE"""),"Cáceres") -> Cáceres | H17: =IFERROR(__xludf.DUMMYFUNCTION("""COMPUTED_VALUE"""),"C202512594841242568") -> C202512594841242568 | I17: =IFERROR(__xludf.DUMMYFUNCTION("""COMPUTED_VALUE"""),"MARIA ISABEL GUERRERO CASTRO") -> MARIA ISABEL GUERRERO CASTRO | J17: =IFERROR(__xludf.DUMMYFUNCTION("""COMPUTED_VALUE"""),45996) -> 45996 | K17: =IFERROR(__xludf.DUMMYFUNCTION("""COMPUTED_VALUE"""),"Factura audífonos") -> Factura audífonos | L17: =IFERROR(__xludf.DUMMYFUNCTION("""COMPUTED_VALUE"""),46035) -> 46035 | M17: =IFERROR(__xludf.DUMMYFUNCTION("""COMPUTED_VALUE"""),"NO") -> NO | N17: =IFERROR(__xludf.DUMMYFUNCTION("""COMPUTED_VALUE"""),1) -> 1 | O17: =IFERROR(__xludf.DUMMYFUNCTION("""COMPUTED_VALUE"""),"PRO") -> PRO | P17: =IFERROR(__xludf.DUMMYFUNCTION("""COMPUTED_VALUE"""),2745) -> 2745 | Q17: =IFERROR(__xludf.DUMMYFUNCTION("""COMPUTED_VALUE"""),"Lisandro Russian") -> Lisandro Russian | R17: =IFERROR(__xludf.DUMMYFUNCTION("""COMPUTED_VALUE"""),"Marta García Jiménez") -> Marta García Jiménez | S17: =IFERROR(__xludf.DUMMYFUNCTION("""COMPUTED_VALUE"""),"03 ORL") -> 03 ORL | T17: =IFERROR(__xludf.DUMMYFUNCTION("""COMPUTED_VALUE"""),"06 ORL") -> 06 ORL
B18: =IF($C18="","",LEFT(C18,3)) -> MBM | C18: =IFERROR(__xludf.DUMMYFUNCTION("""COMPUTED_VALUE"""),"MBM104") -> MBM104 | D18: =IFERROR(__xludf.DUMMYFUNCTION("""COMPUTED_VALUE"""),"PROPIOS") -> PROPIOS | E18: =IFERROR(__xludf.DUMMYFUNCTION("""COMPUTED_VALUE"""),2026) -> 2026 | F18: =IFERROR(__xludf.DUMMYFUNCTION("""COMPUTED_VALUE"""),1) -> 1 | G18: =IFERROR(__xludf.DUMMYFUNCTION("""COMPUTED_VALUE"""),"Fuenlabrada") -> Fuenlabrada | H18: =IFERROR(__xludf.DUMMYFUNCTION("""COMPUTED_VALUE"""),"C202512179181772442") -> C202512179181772442 | I18: =IFERROR(__xludf.DUMMYFUNCTION("""COMPUTED_VALUE"""),"CARMEN DIOS CAAMAÑO") -> CARMEN DIOS CAAMAÑO | J18: =IFERROR(__xludf.DUMMYFUNCTION("""COMPUTED_VALUE"""),46008) -> 46008 | K18: =IFERROR(__xludf.DUMMYFUNCTION("""COMPUTED_VALUE"""),"Factura audífonos") -> Factura audífonos | L18: =IFERROR(__xludf.DUMMYFUNCTION("""COMPUTED_VALUE"""),46035) -> 46035 | M18: =IFERROR(__xludf.DUMMYFUNCTION("""COMPUTED_VALUE"""),"NO") -> NO | N18: =IFERROR(__xludf.DUMMYFUNCTION("""COMPUTED_VALUE"""),1) -> 1 | O18: =IFERROR(__xludf.DUMMYFUNCTION("""COMPUTED_VALUE"""),"CONFORT") -> CONFORT | P18: =IFERROR(__xludf.DUMMYFUNCTION("""COMPUTED_VALUE"""),2180.91) -> 2180.91 | Q18: =IFERROR(__xludf.DUMMYFUNCTION("""COMPUTED_VALUE"""),"Maika Blázquez") -> Maika Blázquez | R18: =IFERROR(__xludf.DUMMYFUNCTION("""COMPUTED_VALUE"""),"Concepcion Rodríguez Izquierdo") -> Concepcion Rodríguez Izquierdo | S18: =IFERROR(__xludf.DUMMYFUNCTION("""COMPUTED_VALUE"""),"03 ORL") -> 03 ORL | T18: =IFERROR(__xludf.DUMMYFUNCTION("""COMPUTED_VALUE"""),"06 ORL") -> 06 ORL
B19: =IF($C19="","",LEFT(C19,3)) -> ISL | C19: =IFERROR(__xludf.DUMMYFUNCTION("""COMPUTED_VALUE"""),"ISL91") -> ISL91 | D19: =IFERROR(__xludf.DUMMYFUNCTION("""COMPUTED_VALUE"""),"PROPIOS") -> PROPIOS | E19: =IFERROR(__xludf.DUMMYFUNCTION("""COMPUTED_VALUE"""),2026) -> 2026 | F19: =IFERROR(__xludf.DUMMYFUNCTION("""COMPUTED_VALUE"""),1) -> 1 | G19: =IFERROR(__xludf.DUMMYFUNCTION("""COMPUTED_VALUE"""),"Murcia") -> Murcia | H19: =IFERROR(__xludf.DUMMYFUNCTION("""COMPUTED_VALUE"""),"C202512121136583127") -> C202512121136583127 | I19: =IFERROR(__xludf.DUMMYFUNCTION("""COMPUTED_VALUE"""),"JESUS MORENO LOPEZ") -> JESUS MORENO LOPEZ | J19: =IFERROR(__xludf.DUMMYFUNCTION("""COMPUTED_VALUE"""),46003) -> 46003 | K19: =IFERROR(__xludf.DUMMYFUNCTION("""COMPUTED_VALUE"""),"Factura audífonos") -> Factura audífonos | L19: =IFERROR(__xludf.DUMMYFUNCTION("""COMPUTED_VALUE"""),46035) -> 46035 | M19: =IFERROR(__xludf.DUMMYFUNCTION("""COMPUTED_VALUE"""),"NO") -> NO | N19: =IFERROR(__xludf.DUMMYFUNCTION("""COMPUTED_VALUE"""),2) -> 2 | O19: =IFERROR(__xludf.DUMMYFUNCTION("""COMPUTED_VALUE"""),"QUIET") -> QUIET | P19: =IFERROR(__xludf.DUMMYFUNCTION("""COMPUTED_VALUE"""),2580.77) -> 2580.77 | Q19: =IFERROR(__xludf.DUMMYFUNCTION("""COMPUTED_VALUE"""),"Iván Sánchez") -> Iván Sánchez | R19: =IFERROR(__xludf.DUMMYFUNCTION("""COMPUTED_VALUE"""),"Alejandra Jara Maquilón") -> Alejandra Jara Maquilón | S19: =IFERROR(__xludf.DUMMYFUNCTION("""COMPUTED_VALUE"""),"03 ORL") -> 03 ORL | T19: =IFERROR(__xludf.DUMMYFUNCTION("""COMPUTED_VALUE"""),"06 ORL") -> 06 ORL
B20: =IF($C20="","",LEFT(C20,3)) -> LAA | C20: =IFERROR(__xludf.DUMMYFUNCTION("""COMPUTED_VALUE"""),"LAA13") -> LAA13 | D20: =IFERROR(__xludf.DUMMYFUNCTION("""COMPUTED_VALUE"""),"PROPIOS") -> PROPIOS | E20: =IFERROR(__xludf.DUMMYFUNCTION("""COMPUTED_VALUE"""),2026) -> 2026 | F20: =IFERROR(__xludf.DUMMYFUNCTION("""COMPUTED_VALUE"""),1) -> 1 | G20: =IFERROR(__xludf.DUMMYFUNCTION("""COMPUTED_VALUE"""),"Sevilla- Montoto") -> Sevilla- Montoto | H20: =IFERROR(__xludf.DUMMYFUNCTION("""COMPUTED_VALUE"""),"C202511241120341965") -> C202511241120341965 | I20: =IFERROR(__xludf.DUMMYFUNCTION("""COMPUTED_VALUE"""),"MIGUEL FONTANILLA RABANEDA") -> MIGUEL FONTANILLA RABANEDA | J20: =IFERROR(__xludf.DUMMYFUNCTION("""COMPUTED_VALUE"""),45985) -> 45985 | K20: =IFERROR(__xludf.DUMMYFUNCTION("""COMPUTED_VALUE"""),"Factura audífonos") -> Factura audífonos | L20: =IFERROR(__xludf.DUMMYFUNCTION("""COMPUTED_VALUE"""),46036) -> 46036 | M20: =IFERROR(__xludf.DUMMYFUNCTION("""COMPUTED_VALUE"""),"NO") -> NO | N20: =IFERROR(__xludf.DUMMYFUNCTION("""COMPUTED_VALUE"""),2) -> 2 | O20: =IFERROR(__xludf.DUMMYFUNCTION("""COMPUTED_VALUE"""),"CONFORT") -> CONFORT | P20: =IFERROR(__xludf.DUMMYFUNCTION("""COMPUTED_VALUE"""),3631.82) -> 3631.82 | Q20: =IFERROR(__xludf.DUMMYFUNCTION("""COMPUTED_VALUE"""),"Luis Alberto Rodríguez") -> Luis Alberto Rodríguez | R20: =IFERROR(__xludf.DUMMYFUNCTION("""COMPUTED_VALUE"""),"Francisco Javier Aguilar Vera") -> Francisco Javier Aguilar Vera | S20: =IFERROR(__xludf.DUMMYFUNCTION("""COMPUTED_VALUE"""),"01 MARKETING ON LINE") -> 01 MARKETING ON LINE | T20: =IFERROR(__xludf.DUMMYFUNCTION("""COMPUTED_VALUE"""),"04 AUDIFONO,ES") -> 04 AUDIFONO,ES
B21: =IF($C21="","",LEFT(C21,3)) -> MBM | C21: =IFERROR(__xludf.DUMMYFUNCTION("""COMPUTED_VALUE"""),"MBM110") -> MBM110 | D21: =IFERROR(__xludf.DUMMYFUNCTION("""COMPUTED_VALUE"""),"PARTICIPADOS") -> PARTICIPADOS | E21: =IFERROR(__xludf.DUMMYFUNCTION("""COMPUTED_VALUE"""),2026) -> 2026 | F21: =IFERROR(__xludf.DUMMYFUNCTION("""COMPUTED_VALUE"""),1) -> 1 | G21: =IFERROR(__xludf.DUMMYFUNCTION("""COMPUTED_VALUE"""),"Madrid- La Oca") -> Madrid- La Oca | H21: =IFERROR(__xludf.DUMMYFUNCTION("""COMPUTED_VALUE"""),"C202512111114179041") -> C202512111114179041 | I21: =IFERROR(__xludf.DUMMYFUNCTION("""COMPUTED_VALUE"""),"PEDRO DOMINGO NAVARRO DIAZ") -> PEDRO DOMINGO NAVARRO DIAZ | J21: =IFERROR(__xludf.DUMMYFUNCTION("""COMPUTED_VALUE"""),46002) -> 46002 | K21: =IFERROR(__xludf.DUMMYFUNCTION("""COMPUTED_VALUE"""),"Factura audífonos") -> Factura audífonos | L21: =IFERROR(__xludf.DUMMYFUNCTION("""COMPUTED_VALUE"""),46036) -> 46036 | M21: =IFERROR(__xludf.DUMMYFUNCTION("""COMPUTED_VALUE"""),"NO") -> NO | N21: =IFERROR(__xludf.DUMMYFUNCTION("""COMPUTED_VALUE"""),2) -> 2 | O21: =IFERROR(__xludf.DUMMYFUNCTION("""COMPUTED_VALUE"""),"QUIET") -> QUIET | P21: =IFERROR(__xludf.DUMMYFUNCTION("""COMPUTED_VALUE"""),2581.82) -> 2581.82 | Q21: =IFERROR(__xludf.DUMMYFUNCTION("""COMPUTED_VALUE"""),"Maika Blázquez") -> Maika Blázquez | R21: =IFERROR(__xludf.DUMMYFUNCTION("""COMPUTED_VALUE"""),"Diana Hernán Pérez") -> Diana Hernán Pérez | S21: =IFERROR(__xludf.DUMMYFUNCTION("""COMPUTED_VALUE"""),"03 ORL") -> 03 ORL | T21: =IFERROR(__xludf.DUMMYFUNCTION("""COMPUTED_VALUE"""),"06 ORL") -> 06 ORL
B22: =IF($C22="","",LEFT(C22,3)) -> ISL | C22: =IFERROR(__xludf.DUMMYFUNCTION("""COMPUTED_VALUE"""),"ISL150") -> ISL150 | D22: =IFERROR(__xludf.DUMMYFUNCTION("""COMPUTED_VALUE"""),"PROPIOS") -> PROPIOS | E22: =IFERROR(__xludf.DUMMYFUNCTION("""COMPUTED_VALUE"""),2026) -> 2026 | F22: =IFERROR(__xludf.DUMMYFUNCTION("""COMPUTED_VALUE"""),1) -> 1 | G22: =IFERROR(__xludf.DUMMYFUNCTION("""COMPUTED_VALUE"""),"Toledo") -> Toledo | H22: =IFERROR(__xludf.DUMMYFUNCTION("""COMPUTED_VALUE"""),"C202512231029369451") -> C202512231029369451 | I22: =IFERROR(__xludf.DUMMYFUNCTION("""COMPUTED_VALUE"""),"Dolores Sanz Contreras") -> Dolores Sanz Contreras | J22: =IFERROR(__xludf.DUMMYFUNCTION("""COMPUTED_VALUE"""),46014) -> 46014 | K22: =IFERROR(__xludf.DUMMYFUNCTION("""COMPUTED_VALUE"""),"Factura audífonos") -> Factura audífonos | L22: =IFERROR(__xludf.DUMMYFUNCTION("""COMPUTED_VALUE"""),46036) -> 46036 | M22: =IFERROR(__xludf.DUMMYFUNCTION("""COMPUTED_VALUE"""),"NO") -> NO | N22: =IFERROR(__xludf.DUMMYFUNCTION("""COMPUTED_VALUE"""),1) -> 1 | O22: =IFERROR(__xludf.DUMMYFUNCTION("""COMPUTED_VALUE"""),"QUIET") -> QUIET | P22: =IFERROR(__xludf.DUMMYFUNCTION("""COMPUTED_VALUE"""),1550.23) -> 1550.23 | Q22: =IFERROR(__xludf.DUMMYFUNCTION("""COMPUTED_VALUE"""),"Lisandro Russian") -> Lisandro Russian | R22: =IFERROR(__xludf.DUMMYFUNCTION("""COMPUTED_VALUE"""),"Alejandra Alvarado Namen") -> Alejandra Alvarado Namen | S22: =IFERROR(__xludf.DUMMYFUNCTION("""COMPUTED_VALUE"""),"03 ORL") -> 03 ORL | T22: =IFERROR(__xludf.DUMMYFUNCTION("""COMPUTED_VALUE"""),"06 ORL") -> 06 ORL
B23: =IF($C23="","",LEFT(C23,3)) -> MBM | C23: =IFERROR(__xludf.DUMMYFUNCTION("""COMPUTED_VALUE"""),"MBM52") -> MBM52 | D23: =IFERROR(__xludf.DUMMYFUNCTION("""COMPUTED_VALUE"""),"PARTICIPADOS") -> PARTICIPADOS | E23: =IFERROR(__xludf.DUMMYFUNCTION("""COMPUTED_VALUE"""),2026) -> 2026 | F23: =IFERROR(__xludf.DUMMYFUNCTION("""COMPUTED_VALUE"""),1) -> 1 | G23: =IFERROR(__xludf.DUMMYFUNCTION("""COMPUTED_VALUE"""),"Madrid- La Oca") -> Madrid- La Oca | H23: =IFERROR(__xludf.DUMMYFUNCTION("""COMPUTED_VALUE"""),"C202512911118838876") -> C202512911118838876 | I23: =IFERROR(__xludf.DUMMYFUNCTION("""COMPUTED_VALUE"""),"MARIA JOSEFA DE MELCHOR DIEZ") -> MARIA JOSEFA DE MELCHOR DIEZ | J23: =IFERROR(__xludf.DUMMYFUNCTION("""COMPUTED_VALUE"""),46000) -> 46000 | K23: =IFERROR(__xludf.DUMMYFUNCTION("""COMPUTED_VALUE"""),"Factura audífonos") -> Factura audífonos | L23: =IFERROR(__xludf.DUMMYFUNCTION("""COMPUTED_VALUE"""),46036) -> 46036 | M23: =IFERROR(__xludf.DUMMYFUNCTION("""COMPUTED_VALUE"""),"NO") -> NO | N23: =IFERROR(__xludf.DUMMYFUNCTION("""COMPUTED_VALUE"""),2) -> 2 | O23: =IFERROR(__xludf.DUMMYFUNCTION("""COMPUTED_VALUE"""),"CONFORT") -> CONFORT | P23: =IFERROR(__xludf.DUMMYFUNCTION("""COMPUTED_VALUE"""),3631.82) -> 3631.82 | Q23: =IFERROR(__xludf.DUMMYFUNCTION("""COMPUTED_VALUE"""),"Maika Blázquez") -> Maika Blázquez | R23: =IFERROR(__xludf.DUMMYFUNCTION("""COMPUTED_VALUE"""),"José Joaquín Gutiérrez Barquín") -> José Joaquín Gutiérrez Barquín | S23: =IFERROR(__xludf.DUMMYFUNCTION("""COMPUTED_VALUE"""),"03 ORL") -> 03 ORL | T23: =IFERROR(__xludf.DUMMYFUNCTION("""COMPUTED_VALUE"""),"06 ORL") -> 06 ORL
B24: =IF($C24="","",LEFT(C24,3)) -> LRM | C24: =IFERROR(__xludf.DUMMYFUNCTION("""COMPUTED_VALUE"""),"LRM239") -> LRM239 | D24: =IFERROR(__xludf.DUMMYFUNCTION("""COMPUTED_VALUE"""),"PROPIOS") -> PROPIOS | E24: =IFERROR(__xludf.DUMMYFUNCTION("""COMPUTED_VALUE"""),2026) -> 2026 | F24: =IFERROR(__xludf.DUMMYFUNCTION("""COMPUTED_VALUE"""),1) -> 1 | G24: =IFERROR(__xludf.DUMMYFUNCTION("""COMPUTED_VALUE"""),"Madrid- Juan Bravo") -> Madrid- Juan Bravo | H24: =IFERROR(__xludf.DUMMYFUNCTION("""COMPUTED_VALUE"""),"C202512181052238972") -> C202512181052238972 | I24: =IFERROR(__xludf.DUMMYFUNCTION("""COMPUTED_VALUE"""),"CONCEPCION FERNANDEZ LOPEZ") -> CONCEPCION FERNANDEZ LOPEZ | J24: =IFERROR(__xludf.DUMMYFUNCTION("""COMPUTED_VALUE"""),46009) -> 46009 | K24: =IFERROR(__xludf.DUMMYFUNCTION("""COMPUTED_VALUE"""),"Factura audífonos") -> Factura audífonos | L24: =IFERROR(__xludf.DUMMYFUNCTION("""COMPUTED_VALUE"""),46036) -> 46036 | M24: =IFERROR(__xludf.DUMMYFUNCTION("""COMPUTED_VALUE"""),"NO") -> NO | N24: =IFERROR(__xludf.DUMMYFUNCTION("""COMPUTED_VALUE"""),2) -> 2 | O24: =IFERROR(__xludf.DUMMYFUNCTION("""COMPUTED_VALUE"""),"ADVANCED") -> ADVANCED | P24: =IFERROR(__xludf.DUMMYFUNCTION("""COMPUTED_VALUE"""),3929.55) -> 3929.55 | Q24: =IFERROR(__xludf.DUMMYFUNCTION("""COMPUTED_VALUE"""),"Lisandro Russian") -> Lisandro Russian | R24: =IFERROR(__xludf.DUMMYFUNCTION("""COMPUTED_VALUE"""),"Carlos Barajas del Rosal") -> Carlos Barajas del Rosal | S24: =IFERROR(__xludf.DUMMYFUNCTION("""COMPUTED_VALUE"""),"03 ORL") -> 03 ORL | T24: =IFERROR(__xludf.DUMMYFUNCTION("""COMPUTED_VALUE"""),"06 ORL") -> 06 ORL
