Workbook

Sheet TOTAL2026
A1: CONTRATO | B1: MES | C1: VISITADOR | D1: CENTRO | E1: COD.CONTRATO | F1: ORL | G1: ACCION MKT | H1: CATEGORÍAS | I1: FECHA P/ | J1: FECHA PAGO | K1: IMPORTE | L1: EMPRESA | M1: OBSERVACIONES | N1: Codigo medico
A2: =IF(C2="","",IFERROR(VLOOKUP($E2,códigos!$R:$R,1,FALSE),"NO")) -> NO | B2: =IFERROR(__xludf.DUMMYFUNCTION("{FILTER(ENERO!A4:K1001,ENERO!C4:C1001<>"""");FILTER(FEBRERO!A4:K1001,FEBRERO!C4:C1001<>"""");FILTER(MARZO!A4:K1001,MARZO!C4:C1001<>"""");FILTER(ABRIL!A4:K1001,ABRIL!C4:C1001<>"""");FILTER(MAYO!A4:K1001,MAYO!C4:C1001<>"""");FILTER(JUNIO!A4:K1001,JUNIO!C4:C"&"1001<>"""");FILTER(JULIO!A4:K1001,JULIO!C4:C1001<>"""");FILTER(AGOSTO!A4:K1001,AGOSTO!C4:C1001<>"""");FILTER(SEPTIEMBRE!A4:K1001,SEPTIEMBRE!C4:C1001<>"""");FILTER(OCTUBRE!A4:K1001,OCTUBRE!C4:C1001<>"""");FILTER(NOVIEMBRE!A4:K1001,NOVIEMBRE!C4:C1001<>"""")"&";FILTER(DICIEMBRE!A4:K1001,DICIEMBRE!C4:C1001<>"""")}"),1) -> 1 | C2: =IFERROR(__xludf.DUMMYFUNCTION("""COMPUTED_VALUE"""),"Luis Alberto Rodríguez") -> Luis Alberto Rodríguez | D2: =IFERROR(__xludf.DUMMYFUNCTION("""COMPUTED_VALUE"""),"Jerez de la Frontera") -> Jerez de la Frontera | E2: =IFERROR(__xludf.DUMMYFUNCTION("""COMPUTED_VALUE"""),"LAA78") -> LAA78 | F2: =IFERROR(__xludf.DUMMYFUNCTION("""COMPUTED_VALUE"""),"Maria Del Carmen Salom Coveñas") -> Maria Del Carmen Salom Coveñas | G2: =IFERROR(__xludf.DUMMYFUNCTION("""COMPUTED_VALUE"""),"PATROCINIO") -> PATROCINIO | H2: =IFERROR(__xludf.DUMMYFUNCTION("""COMPUTED_VALUE"""),"Publicidad") -> Publicidad | J2: =IFERROR(__xludf.DUMMYFUNCTION("""COMPUTED_VALUE"""),46034) -> 46034 | K2: =IFERROR(__xludf.DUMMYFUNCTION("""COMPUTED_VALUE"""),-4432) -> -4432 | L2: =IFERROR(__xludf.DUMMYFUNCTION("""COMPUTED_VALUE"""),"AUDICOST, S.L.U") -> AUDICOST, S.L.U
A3: =IF(C3="","",IFERROR(VLOOKUP($E3,códigos!$R:$R,1,FALSE),"NO")) -> NO | B3: =IFERROR(__xludf.DUMMYFUNCTION("""COMPUTED_VALUE"""),1) -> 1 | C3: =IFERROR(__xludf.DUMMYFUNCTION("""COMPUTED_VALUE"""),"Maika Blázquez") -> Maika Blázquez | D3: =IFERROR(__xludf.DUMMYFUNCTION("""COMPUTED_VALUE"""),"Getafe") -> Getafe | E3: =IFERROR(__xludf.DUMMYFUNCTION("""COMPUTED_VALUE"""),"MBM149") -> MBM149 | F3: =IFERROR(__xludf.DUMMYFUNCTION("""COMPUTED_VALUE"""),"María Garrote Garrote") -> María Garrote Garrote | G3: =IFERROR(__xludf.DUMMYFUNCTION("""COMPUTED_VALUE"""),"AIRBNB") -> AIRBNB | H3: =IFERROR(__xludf.DUMMYFUNCTION("""COMPUTED_VALUE"""),"Alojamiento") -> Alojamiento | I3: =IFERROR(__xludf.DUMMYFUNCTION("""COMPUTED_VALUE"""),46036) -> 46036 | J3: =IFERROR(__xludf.DUMMYFUNCTION("""COMPUTED_VALUE"""),46034) -> 46034 | K3: =IFERROR(__xludf.DUMMYFUNCTION("""COMPUTED_VALUE"""),-1700) -> -1700 | L3: =IFERROR(__xludf.DUMMYFUNCTION("""COMPUTED_VALUE"""),"AUDIBRADA") -> AUDIBRADA
A4: =IF(C4="","",IFERROR(VLOOKUP($E4,códigos!$R:$R,1,FALSE),"NO")) -> NO | B4: =IFERROR(__xludf.DUMMYFUNCTION("""COMPUTED_VALUE"""),1) -> 1 | C4: =IFERROR(__xludf.DUMMYFUNCTION("""COMPUTED_VALUE"""),"Maika Blázquez") -> Maika Blázquez | D4: =IFERROR(__xludf.DUMMYFUNCTION("""COMPUTED_VALUE"""),"Fuenlabrada") -> Fuenlabrada | E4: =IFERROR(__xludf.DUMMYFUNCTION("""COMPUTED_VALUE"""),"MBM164") -> MBM164 | F4: =IFERROR(__xludf.DUMMYFUNCTION("""COMPUTED_VALUE"""),"Paloma Martín-Aragón Martín") -> Paloma Martín-Aragón Martín | G4: =IFERROR(__xludf.DUMMYFUNCTION("""COMPUTED_VALUE"""),"INSCRIPCION CURSO MICROCIRUGIA") -> INSCRIPCION CURSO MICROCIRUGIA | H4: =IFERROR(__xludf.DUMMYFUNCTION("""COMPUTED_VALUE"""),"Inscripción") -> Inscripción | J4: =IFERROR(__xludf.DUMMYFUNCTION("""COMPUTED_VALUE"""),46035) -> 46035 | K4: =IFERROR(__xludf.DUMMYFUNCTION("""COMPUTED_VALUE"""),-1663.35) -> -1663.35 | L4: =IFERROR(__xludf.DUMMYFUNCTION("""COMPUTED_VALUE"""),"AUDIBRADA") -> AUDIBRADA
A5: =IF(C5="","",IFERROR(VLOOKUP($E5,códigos!$R:$R,1,FALSE),"NO")) -> NO | B5: =IFERROR(__xludf.DUMMYFUNCTION("""COMPUTED_VALUE"""),1) -> 1 | C5: =IFERROR(__xludf.DUMMYFUNCTION("""COMPUTED_VALUE"""),"Maika Blázquez") -> Maika Blázquez | D5: =IFERROR(__xludf.DUMMYFUNCTION("""COMPUTED_VALUE"""),"Fuenlabrada") -> Fuenlabrada | E5: =IFERROR(__xludf.DUMMYFUNCTION("""COMPUTED_VALUE"""),"MBM111") -> MBM111 | F5: =IFERROR(__xludf.DUMMYFUNCTION("""COMPUTED_VALUE"""),"Elisabeth Amarillo Espitia") -> Elisabeth Amarillo Espitia | G5: =IFERROR(__xludf.DUMMYFUNCTION("""COMPUTED_VALUE"""),"INSCRIPCION CURSO MICROCIRUGIA") -> INSCRIPCION CURSO MICROCIRUGIA | H5: =IFERROR(__xludf.DUMMYFUNCTION("""COMPUTED_VALUE"""),"Inscripción") -> Inscripción | J5: =IFERROR(__xludf.DUMMYFUNCTION("""COMPUTED_VALUE"""),46035) -> 46035 | K5: =IFERROR(__xludf.DUMMYFUNCTION("""COMPUTED_VALUE"""),-1663.35) -> -1663.35 | L5: =IFERROR(__xludf.DUMMYFUNCTION("""COMPUTED_VALUE"""),"AUDIBRADA") -> AUDIBRADA
A6: =IF(C6="","",IFERROR(VLOOKUP($E6,códigos!$R:$R,1,FALSE),"NO")) -> NO | B6: =IFERROR(__xludf.DUMMYFUNCTION("""COMPUTED_VALUE"""),1) -> 1 | C6: =IFERROR(__xludf.DUMMYFUNCTION("""COMPUTED_VALUE"""),"Maika Blázquez") -> Maika Blázquez | D6: =IFERROR(__xludf.DUMMYFUNCTION("""COMPUTED_VALUE"""),"Madrid- Canillas") -> Madrid- Canillas | E6: =IFERROR(__xludf.DUMMYFUNCTION("""COMPUTED_VALUE"""),"MBM50") -> MBM50 | F6: =IFERROR(__xludf.DUMMYFUNCTION("""COMPUTED_VALUE"""),"José Gustavo Barroso Braojos") -> José Gustavo Barroso Braojos | G6: =IFERROR(__xludf.DUMMYFUNCTION("""COMPUTED_VALUE"""),"2 SMARTWATCH") -> 2 SMARTWATCH | H6: =IFERROR(__xludf.DUMMYFUNCTION("""COMPUTED_VALUE"""),"Material para centro") -> Material para centro | I6: =IFERROR(__xludf.DUMMYFUNCTION("""COMPUTED_VALUE"""),46036) -> 46036 | J6: =IFERROR(__xludf.DUMMYFUNCTION("""COMPUTED_VALUE"""),46035) -> 46035 | K6: =IFERROR(__xludf.DUMMYFUNCTION("""COMPUTED_VALUE"""),-899.98) -> -899.98 | L6: =IFERROR(__xludf.DUMMYFUNCTION("""COMPUTED_VALUE"""),"AUDICOST, S.L.U") -> AUDICOST, S.L.U
A7: =IF(C7="","",IFERROR(VLOOKUP($E7,códigos!$R:$R,1,FALSE),"NO")) -> NO | B7: =IFERROR(__xludf.DUMMYFUNCTION("""COMPUTED_VALUE"""),1) -> 1 | C7: =IFERROR(__xludf.DUMMYFUNCTION("""COMPUTED_VALUE"""),"Luis Alberto Rodríguez") -> Luis Alberto Rodríguez | D7: =IFERROR(__xludf.DUMMYFUNCTION("""COMPUTED_VALUE"""),"Sevilla- Montoto") -> Sevilla- Montoto | E7: =IFERROR(__xludf.DUMMYFUNCTION("""COMPUTED_VALUE"""),"LAA08") -> LAA08 | F7: =IFERROR(__xludf.DUMMYFUNCTION("""COMPUTED_VALUE"""),"David Castro Gutiérrez de Agüero") -> David Castro Gutiérrez de Agüero | G7: =IFERROR(__xludf.DUMMYFUNCTION("""COMPUTED_VALUE"""),"IPHONE17 PRO") -> IPHONE17 PRO | H7: =IFERROR(__xludf.DUMMYFUNCTION("""COMPUTED_VALUE"""),"Material para centro") -> Material para centro | I7: =IFERROR(__xludf.DUMMYFUNCTION("""COMPUTED_VALUE"""),46042) -> 46042 | J7: =IFERROR(__xludf.DUMMYFUNCTION("""COMPUTED_VALUE"""),46037) -> 46037 | K7: =IFERROR(__xludf.DUMMYFUNCTION("""COMPUTED_VALUE"""),-1289) -> -1289 | L7: =IFERROR(__xludf.DUMMYFUNCTION("""COMPUTED_VALUE"""),"OIR VITAL CENTROS AUDITIVOS ") -> OIR VITAL CENTROS AUDITIVOS
A8: =IF(C8="","",IFERROR(VLOOKUP($E8,códigos!$R:$R,1,FALSE),"NO")) -> NO | B8: =IFERROR(__xludf.DUMMYFUNCTION("""COMPUTED_VALUE"""),1) -> 1 | C8: =IFERROR(__xludf.DUMMYFUNCTION("""COMPUTED_VALUE"""),"Maika Blázquez") -> Maika Blázquez | D8: =IFERROR(__xludf.DUMMYFUNCTION("""COMPUTED_VALUE"""),"Torrejón De Ardoz") -> Torrejón De Ardoz | E8: =IFERROR(__xludf.DUMMYFUNCTION("""COMPUTED_VALUE"""),"MBM136") -> MBM136 | F8: =IFERROR(__xludf.DUMMYFUNCTION("""COMPUTED_VALUE"""),"Lorena Sanz López") -> Lorena Sanz López | G8: =IFERROR(__xludf.DUMMYFUNCTION("""COMPUTED_VALUE"""),"INSCRIPCION, VUELO Y HOTEL-MAYOR IMPORTE DICBRE.") -> INSCRIPCION, VUELO Y HOTEL-MAYOR IMPORTE DICBRE. | H8: =IFERROR(__xludf.DUMMYFUNCTION("""COMPUTED_VALUE"""),"Inscripción") -> Inscripción | I8: =IFERROR(__xludf.DUMMYFUNCTION("""COMPUTED_VALUE"""),46042) -> 46042 | J8: =IFERROR(__xludf.DUMMYFUNCTION("""COMPUTED_VALUE"""),46041) -> 46041 | K8: =IFERROR(__xludf.DUMMYFUNCTION("""COMPUTED_VALUE"""),-205.75) -> -205.75 | L8: =IFERROR(__xludf.DUMMYFUNCTION("""COMPUTED_VALUE"""),"AUDICOST LEGANES") -> AUDICOST LEGANES
A9: =IF(C9="","",IFERROR(VLOOKUP($E9,códigos!$R:$R,1,FALSE),"NO")) -> NO | B9: =IFERROR(__xludf.DUMMYFUNCTION("""COMPUTED_VALUE"""),1) -> 1 | C9: =IFERROR(__xludf.DUMMYFUNCTION("""COMPUTED_VALUE"""),"Maika Blázquez") -> Maika Blázquez | D9: =IFERROR(__xludf.DUMMYFUNCTION("""COMPUTED_VALUE"""),"Madrid- La Oca") -> Madrid- La Oca | E9: =IFERROR(__xludf.DUMMYFUNCTION("""COMPUTED_VALUE"""),"MBM52") -> MBM52 | F9: =IFERROR(__xludf.DUMMYFUNCTION("""COMPUTED_VALUE"""),"José Joaquín Gutiérrez Barquín") -> José Joaquín Gutiérrez Barquín | G9: =IFERROR(__xludf.DUMMYFUNCTION("""COMPUTED_VALUE"""),"MESA") -> MESA | H9: =IFERROR(__xludf.DUMMYFUNCTION("""COMPUTED_VALUE"""),"Mobiliario") -> Mobiliario | I9: =IFERROR(__xludf.DUMMYFUNCTION("""COMPUTED_VALUE"""),46044) -> 46044 | J9: =IFERROR(__xludf.DUMMYFUNCTION("""COMPUTED_VALUE"""),46042) -> 46042 | K9: =IFERROR(__xludf.DUMMYFUNCTION("""COMPUTED_VALUE"""),-973) -> -973 | L9: =IFERROR(__xludf.DUMMYFUNCTION("""COMPUTED_VALUE"""),"SIEMA BLINK, S.L") -> SIEMA BLINK, S.L
A10: =IF(C10="","",IFERROR(VLOOKUP($E10,códigos!$R:$R,1,FALSE),"NO")) -> NO | B10: =IFERROR(__xludf.DUMMYFUNCTION("""COMPUTED_VALUE"""),1) -> 1 | C10: =IFERROR(__xludf.DUMMYFUNCTION("""COMPUTED_VALUE"""),"Maika Blázquez") -> Maika Blázquez | D10: =IFERROR(__xludf.DUMMYFUNCTION("""COMPUTED_VALUE"""),"Fuenlabrada") -> Fuenlabrada | E10: =IFERROR(__xludf.DUMMYFUNCTION("""COMPUTED_VALUE"""),"MBM190") -> MBM190 | F10: =IFERROR(__xludf.DUMMYFUNCTION("""COMPUTED_VALUE"""),"Cristina García García") -> Cristina García García | G10: =IFERROR(__xludf.DUMMYFUNCTION("""COMPUTED_VALUE"""),"CURSO 2") -> CURSO 2 | H10: =IFERROR(__xludf.DUMMYFUNCTION("""COMPUTED_VALUE"""),"Inscripción") -> Inscripción | I10: =IFERROR(__xludf.DUMMYFUNCTION("""COMPUTED_VALUE""")," ") | J10: =IFERROR(__xludf.DUMMYFUNCTION("""COMPUTED_VALUE"""),46043) -> 46043 | K10: =IFERROR(__xludf.DUMMYFUNCTION("""COMPUTED_VALUE"""),-1386.13) -> -1386.13 | L10: =IFERROR(__xludf.DUMMYFUNCTION("""COMPUTED_VALUE"""),"AUDIBRADA") -> AUDIBRADA
A11: =IF(C11="","",IFERROR(VLOOKUP($E11,códigos!$R:$R,1,FALSE),"NO")) -> NO | B11: =IFERROR(__xludf.DUMMYFUNCTION("""COMPUTED_VALUE"""),1) -> 1 | C11: =IFERROR(__xludf.DUMMYFUNCTION("""COMPUTED_VALUE"""),"Maika Blázquez") -> Maika Blázquez | D11: =IFERROR(__xludf.DUMMYFUNCTION("""COMPUTED_VALUE"""),"Fuenlabrada") -> Fuenlabrada | E11: =IFERROR(__xludf.DUMMYFUNCTION("""COMPUTED_VALUE"""),"MBM190") -> MBM190 | F11: =IFERROR(__xludf.DUMMYFUNCTION("""COMPUTED_VALUE"""),"Cristina García García") -> Cristina García García | G11: =IFERROR(__xludf.DUMMYFUNCTION("""COMPUTED_VALUE"""),"CURSO 1") -> CURSO 1 | H11: =IFERROR(__xludf.DUMMYFUNCTION("""COMPUTED_VALUE"""),"Inscripción") -> Inscripción | I11: =IFERROR(__xludf.DUMMYFUNCTION("""COMPUTED_VALUE""")," ") | J11: =IFERROR(__xludf.DUMMYFUNCTION("""COMPUTED_VALUE"""),46043) -> 46043 | K11: =IFERROR(__xludf.DUMMYFUNCTION("""COMPUTED_VALUE"""),-1386.13) -> -1386.13 | L11: =IFERROR(__xludf.DUMMYFUNCTION("""COMPUTED_VALUE"""),"AUDIBRADA") -> AUDIBRADA
A12: =IF(C12="","",IFERROR(VLOOKUP($E12,códigos!$R:$R,1,FALSE),"NO")) -> NO | B12: =IFERROR(__xludf.DUMMYFUNCTION("""COMPUTED_VALUE"""),1) -> 1 | C12: =IFERROR(__xludf.DUMMYFUNCTION("""COMPUTED_VALUE"""),"Maika Blázquez") -> Maika Blázquez | D12: =IFERROR(__xludf.DUMMYFUNCTION("""COMPUTED_VALUE"""),"Madrid- Juan Bravo") -> Madrid- Juan Bravo | E12: =IFERROR(__xludf.DUMMYFUNCTION("""COMPUTED_VALUE"""),"MBM224") -> MBM224 | F12: =IFERROR(__xludf.DUMMYFUNCTION("""COMPUTED_VALUE"""),"Roberto Sanz Garzón") -> Roberto Sanz Garzón | G12: =IFERROR(__xludf.DUMMYFUNCTION("""COMPUTED_VALUE"""),"CURSO") -> CURSO | H12: =IFERROR(__xludf.DUMMYFUNCTION("""COMPUTED_VALUE"""),"Inscripción") -> Inscripción | I12: =IFERROR(__xludf.DUMMYFUNCTION("""COMPUTED_VALUE"""),46043) -> 46043 | J12: =IFERROR(__xludf.DUMMYFUNCTION("""COMPUTED_VALUE"""),46043) -> 46043 | K12: =IFERROR(__xludf.DUMMYFUNCTION("""COMPUTED_VALUE"""),-600) -> -600 | L12: =IFERROR(__xludf.DUMMYFUNCTION("""COMPUTED_VALUE"""),"AUDICOST, S.L.U") -> AUDICOST, S.L.U
A13: =IF(C13="","",IFERROR(VLOOKUP($E13,códigos!$R:$R,1,FALSE),"NO")) -> NO | B13: =IFERROR(__xludf.DUMMYFUNCTION("""COMPUTED_VALUE"""),1) -> 1 | C13: =IFERROR(__xludf.DUMMYFUNCTION("""COMPUTED_VALUE"""),"Lisandro Russian") -> Lisandro Russian | D13: =IFERROR(__xludf.DUMMYFUNCTION("""COMPUTED_VALUE"""),"Logroño") -> Logroño | E13: =IFERROR(__xludf.DUMMYFUNCTION("""COMPUTED_VALUE"""),"LRM151") -> LRM151 | F13: =IFERROR(__xludf.DUMMYFUNCTION("""COMPUTED_VALUE"""),"Cristina Ibañez Muñoz") -> Cristina Ibañez Muñoz | G13: =IFERROR(__xludf.DUMMYFUNCTION("""COMPUTED_VALUE"""),"CONGRESO ATENAS") -> CONGRESO ATENAS | H13: =IFERROR(__xludf.DUMMYFUNCTION("""COMPUTED_VALUE"""),"Congreso internacional personal") -> Congreso internacional personal | I13: =IFERROR(__xludf.DUMMYFUNCTION("""COMPUTED_VALUE"""),46058) -> 46058 | J13: =IFERROR(__xludf.DUMMYFUNCTION("""COMPUTED_VALUE"""),46044) -> 46044 | K13: =IFERROR(__xludf.DUMMYFUNCTION("""COMPUTED_VALUE"""),-4701.07) -> -4701.07 | L13: =IFERROR(__xludf.DUMMYFUNCTION("""COMPUTED_VALUE"""),"AUDICOST LOGROÑO ") -> AUDICOST LOGROÑO
A14: =IF(C14="","",IFERROR(VLOOKUP($E14,códigos!$R:$R,1,FALSE),"NO")) -> NO | B14: =IFERROR(__xludf.DUMMYFUNCTION("""COMPUTED_VALUE"""),1) -> 1 | C14: =IFERROR(__xludf.DUMMYFUNCTION("""COMPUTED_VALUE"""),"Ramon Ferrando") -> Ramon Ferrando | D14: =IFERROR(__xludf.DUMMYFUNCTION("""COMPUTED_VALUE"""),"El Albir (Benidorm)") -> El Albir (Benidorm) | E14: =IFERROR(__xludf.DUMMYFUNCTION("""COMPUTED_VALUE"""),"RFV38") -> RFV38 | F14: =IFERROR(__xludf.DUMMYFUNCTION("""COMPUTED_VALUE"""),"María Emilia García Ruiz") -> María Emilia García Ruiz | G14: =IFERROR(__xludf.DUMMYFUNCTION("""COMPUTED_VALUE"""),"IPHONE17 ") -> IPHONE17 | H14: =IFERROR(__xludf.DUMMYFUNCTION("""COMPUTED_VALUE"""),"Material para centro") -> Material para centro | J14: =IFERROR(__xludf.DUMMYFUNCTION("""COMPUTED_VALUE"""),46045) -> 46045 | K14: =IFERROR(__xludf.DUMMYFUNCTION("""COMPUTED_VALUE"""),-1500) -> -1500 | L14: =IFERROR(__xludf.DUMMYFUNCTION("""COMPUTED_VALUE"""),"AUDICANTE") -> AUDICANTE
A15: =IF(C15="","",IFERROR(VLOOKUP($E15,códigos!$R:$R,1,FALSE),"NO")) -> NO | B15: =IFERROR(__xludf.DUMMYFUNCTION("""COMPUTED_VALUE"""),1) -> 1 | C15: =IFERROR(__xludf.DUMMYFUNCTION("""COMPUTED_VALUE"""),"Maika Blázquez") -> Maika Blázquez | D15: =IFERROR(__xludf.DUMMYFUNCTION("""COMPUTED_VALUE"""),"Torrejón De Ardoz") -> Torrejón De Ardoz | E15: =IFERROR(__xludf.DUMMYFUNCTION("""COMPUTED_VALUE"""),"MBM187") -> MBM187 | F15: =IFERROR(__xludf.DUMMYFUNCTION("""COMPUTED_VALUE"""),"Abel Bogoya Castaño") -> Abel Bogoya Castaño | G15: =IFERROR(__xludf.DUMMYFUNCTION("""COMPUTED_VALUE"""),"CURSO") -> CURSO | H15: =IFERROR(__xludf.DUMMYFUNCTION("""COMPUTED_VALUE"""),"Inscripción") -> Inscripción | L15: =IFERROR(__xludf.DUMMYFUNCTION("""COMPUTED_VALUE"""),"AUDICOST LEGANES") -> AUDICOST LEGANES
A16: =IF(C16="","",IFERROR(VLOOKUP($E16,códigos!$R:$R,1,FALSE),"NO")) -> NO | B16: =IFERROR(__xludf.DUMMYFUNCTION("""COMPUTED_VALUE"""),1) -> 1 | C16: =IFERROR(__xludf.DUMMYFUNCTION("""COMPUTED_VALUE"""),"Ramon Ferrando") -> Ramon Ferrando | D16: =IFERROR(__xludf.DUMMYFUNCTION("""COMPUTED_VALUE"""),"Valencia- Cadiz") -> Valencia- Cadiz | E16: =IFERROR(__xludf.DUMMYFUNCTION("""COMPUTED_VALUE"""),"RFV48") -> RFV48 | F16: =IFERROR(__xludf.DUMMYFUNCTION("""COMPUTED_VALUE"""),"Elena González Turienzo") -> Elena González Turienzo | G16: =IFERROR(__xludf.DUMMYFUNCTION("""COMPUTED_VALUE"""),"CURSO") -> CURSO | H16: =IFERROR(__xludf.DUMMYFUNCTION("""COMPUTED_VALUE"""),"Inscripción") -> Inscripción | I16: =IFERROR(__xludf.DUMMYFUNCTION("""COMPUTED_VALUE"""),46058) -> 46058 | J16: =IFERROR(__xludf.DUMMYFUNCTION("""COMPUTED_VALUE"""),46049) -> 46049 | K16: =IFERROR(__xludf.DUMMYFUNCTION("""COMPUTED_VALUE"""),-133.07) -> -133.07 | L16: =IFERROR(__xludf.DUMMYFUNCTION("""COMPUTED_VALUE"""),"AUDICANTE") -> AUDICANTE
A17: =IF(C17="","",IFERROR(VLOOKUP($E17,códigos!$R:$R,1,FALSE),"NO")) -> NO | B17: =IFERROR(__xludf.DUMMYFUNCTION("""COMPUTED_VALUE"""),2) -> 2 | C17: =IFERROR(__xludf.DUMMYFUNCTION("""COMPUTED_VALUE"""),"Maika Blázquez") -> Maika Blázquez | D17: =IFERROR(__xludf.DUMMYFUNCTION("""COMPUTED_VALUE"""),"Torrejón De Ardoz") -> Torrejón De Ardoz | E17: =IFERROR(__xludf.DUMMYFUNCTION("""COMPUTED_VALUE"""),"MBM61") -> MBM61 | F17: =IFERROR(__xludf.DUMMYFUNCTION("""COMPUTED_VALUE"""),"Julie Múñoz Freitez") -> Julie Múñoz Freitez | G17: =IFERROR(__xludf.DUMMYFUNCTION("""COMPUTED_VALUE"""),"CURSO") -> CURSO | H17: =IFERROR(__xludf.DUMMYFUNCTION("""COMPUTED_VALUE"""),"Inscripción") -> Inscripción | I17: =IFERROR(__xludf.DUMMYFUNCTION("""COMPUTED_VALUE"""),46062) -> 46062 | J17: =IFERROR(__xludf.DUMMYFUNCTION("""COMPUTED_VALUE"""),46056) -> 46056 | K17: =IFERROR(__xludf.DUMMYFUNCTION("""COMPUTED_VALUE"""),-2772.25) -> -2772.25 | L17: =IFERROR(__xludf.DUMMYFUNCTION("""COMPUTED_VALUE"""),"AUDICOST LEGANES") -> AUDICOST LEGANES
A18: =IF(C18="","",IFERROR(VLOOKUP($E18,códigos!$R:$R,1,FALSE),"NO")) -> NO | B18: =IFERROR(__xludf.DUMMYFUNCTION("""COMPUTED_VALUE"""),2) -> 2 | C18: =IFERROR(__xludf.DUMMYFUNCTION("""COMPUTED_VALUE"""),"Maika Blázquez") -> Maika Blázquez | D18: =IFERROR(__xludf.DUMMYFUNCTION("""COMPUTED_VALUE"""),"Fuenlabrada") -> Fuenlabrada | E18: =IFERROR(__xludf.DUMMYFUNCTION("""COMPUTED_VALUE"""),"MBM147") -> MBM147 | F18: =IFERROR(__xludf.DUMMYFUNCTION("""COMPUTED_VALUE"""),"María Estefanía Hernández García") -> María Estefanía Hernández García | G18: =IFERROR(__xludf.DUMMYFUNCTION("""COMPUTED_VALUE"""),"CURSO") -> CURSO | H18: =IFERROR(__xludf.DUMMYFUNCTION("""COMPUTED_VALUE"""),"Inscripción") -> Inscripción | I18: =IFERROR(__xludf.DUMMYFUNCTION("""COMPUTED_VALUE"""),46064) -> 46064 | J18: =IFERROR(__xludf.DUMMYFUNCTION("""COMPUTED_VALUE"""),46056) -> 46056 | K18: =IFERROR(__xludf.DUMMYFUNCTION("""COMPUTED_VALUE"""),-443.56) -> -443.56 | L18: =IFERROR(__xludf.DUMMYFUNCTION("""COMPUTED_VALUE"""),"AUDIBRADA") -> AUDIBRADA
A19: =IF(C19="","",IFERROR(VLOOKUP($E19,códigos!$R:$R,1,FALSE),"NO")) -> NO | B19: =IFERROR(__xludf.DUMMYFUNCTION("""COMPUTED_VALUE"""),2) -> 2 | C19: =IFERROR(__xludf.DUMMYFUNCTION("""COMPUTED_VALUE"""),"Ramon Ferrando") -> Ramon Ferrando | D19: =IFERROR(__xludf.DUMMYFUNCTION("""COMPUTED_VALUE"""),"Valencia- Parra") -> Valencia- Parra | E19: =IFERROR(__xludf.DUMMYFUNCTION("""COMPUTED_VALUE"""),"RFV15") -> RFV15 | F19: =IFERROR(__xludf.DUMMYFUNCTION("""COMPUTED_VALUE"""),"Jean Franco Intraprendente Martini") -> Jean Franco Intraprendente Martini | G19: =IFERROR(__xludf.DUMMYFUNCTION("""COMPUTED_VALUE"""),"APPLEWATCH") -> APPLEWATCH | H19: =IFERROR(__xludf.DUMMYFUNCTION("""COMPUTED_VALUE"""),"Material para centro") -> Material para centro | J19: =IFERROR(__xludf.DUMMYFUNCTION("""COMPUTED_VALUE"""),46055) -> 46055 | K19: =IFERROR(__xludf.DUMMYFUNCTION("""COMPUTED_VALUE"""),-899) -> -899 | L19: =IFERROR(__xludf.DUMMYFUNCTION("""COMPUTED_VALUE"""),"AUDICOST, S.L.U") -> AUDICOST, S.L.U
A20: =IF(C20="","",IFERROR(VLOOKUP($E20,códigos!$R:$R,1,FALSE),"NO")) -> NO | B20: =IFERROR(__xludf.DUMMYFUNCTION("""COMPUTED_VALUE"""),2) -> 2 | C20: =IFERROR(__xludf.DUMMYFUNCTION("""COMPUTED_VALUE"""),"Iván Sánchez") -> Iván Sánchez | D20: =IFERROR(__xludf.DUMMYFUNCTION("""COMPUTED_VALUE"""),"El Albir (Benidorm)") -> El Albir (Benidorm) | E20: =IFERROR(__xludf.DUMMYFUNCTION("""COMPUTED_VALUE"""),"ISL54") -> ISL54 | F20: =IFERROR(__xludf.DUMMYFUNCTION("""COMPUTED_VALUE"""),"José María Laborda Margolles") -> José María Laborda Margolles | G20: =IFERROR(__xludf.DUMMYFUNCTION("""COMPUTED_VALUE"""),"VIAJE A TANZANIA") -> VIAJE A TANZANIA | H20: =IFERROR(__xludf.DUMMYFUNCTION("""COMPUTED_VALUE"""),"Congreso internacional") -> Congreso internacional | I20: =IFERROR(__xludf.DUMMYFUNCTION("""COMPUTED_VALUE"""),46059) -> 46059 | J20: =IFERROR(__xludf.DUMMYFUNCTION("""COMPUTED_VALUE"""),46059) -> 46059 | K20: =IFERROR(__xludf.DUMMYFUNCTION("""COMPUTED_VALUE"""),-4000) -> -4000 | L20: =IFERROR(__xludf.DUMMYFUNCTION("""COMPUTED_VALUE"""),"AUDICANTE") -> AUDICANTE
A21: =IF(C21="","",IFERROR(VLOOKUP($E21,códigos!$R:$R,1,FALSE),"NO")) -> NO | B21: =IFERROR(__xludf.DUMMYFUNCTION("""COMPUTED_VALUE"""),2) -> 2 | C21: =IFERROR(__xludf.DUMMYFUNCTION("""COMPUTED_VALUE"""),"Lisandro Russian") -> Lisandro Russian | D21: =IFERROR(__xludf.DUMMYFUNCTION("""COMPUTED_VALUE"""),"Logroño") -> Logroño | E21: =IFERROR(__xludf.DUMMYFUNCTION("""COMPUTED_VALUE"""),"LRM264") -> LRM264 | F21: =IFERROR(__xludf.DUMMYFUNCTION("""COMPUTED_VALUE"""),"Carmen Delgado Muñoz") -> Carmen Delgado Muñoz | G21: =IFERROR(__xludf.DUMMYFUNCTION("""COMPUTED_VALUE"""),"IPHONE15") -> IPHONE15 | H21: =IFERROR(__xludf.DUMMYFUNCTION("""COMPUTED_VALUE"""),"Material para centro") -> Material para centro | J21: =IFERROR(__xludf.DUMMYFUNCTION("""COMPUTED_VALUE"""),46049) -> 46049 | K21: =IFERROR(__xludf.DUMMYFUNCTION("""COMPUTED_VALUE"""),-626.99) -> -626.99 | L21: =IFERROR(__xludf.DUMMYFUNCTION("""COMPUTED_VALUE"""),"AUDICOST LOGROÑO ") -> AUDICOST LOGROÑO
A22: =IF(C22="","",IFERROR(VLOOKUP($E22,códigos!$R:$R,1,FALSE),"NO")) -> NO | B22: =IFERROR(__xludf.DUMMYFUNCTION("""COMPUTED_VALUE"""),1) -> 1 | C22: =IFERROR(__xludf.DUMMYFUNCTION("""COMPUTED_VALUE"""),"Lisandro Russian") -> Lisandro Russian | D22: =IFERROR(__xludf.DUMMYFUNCTION("""COMPUTED_VALUE"""),"Alcorcón") -> Alcorcón | E22: =IFERROR(__xludf.DUMMYFUNCTION("""COMPUTED_VALUE"""),"LRM82") -> LRM82 | F22: =IFERROR(__xludf.DUMMYFUNCTION("""COMPUTED_VALUE"""),"José Miguel Aparicio Fernández") -> José Miguel Aparicio Fernández | G22: =IFERROR(__xludf.DUMMYFUNCTION("""COMPUTED_VALUE"""),"CURSO PARA R4 TERESA CONDE GOMEZ-MENOR") -> CURSO PARA R4 TERESA CONDE GOMEZ-MENOR | H22: =IFERROR(__xludf.DUMMYFUNCTION("""COMPUTED_VALUE"""),"Inscripción") -> Inscripción | I22: =IFERROR(__xludf.DUMMYFUNCTION("""COMPUTED_VALUE"""),46062) -> 46062 | J22: =IFERROR(__xludf.DUMMYFUNCTION("""COMPUTED_VALUE"""),46036) -> 46036 | K22: =IFERROR(__xludf.DUMMYFUNCTION("""COMPUTED_VALUE"""),-310.5) -> -310.5 | L22: =IFERROR(__xludf.DUMMYFUNCTION("""COMPUTED_VALUE"""),"CLINICA DOS DE MAYO ") -> CLINICA DOS DE MAYO
A23: =IF(C23="","",IFERROR(VLOOKUP($E23,códigos!$R:$R,1,FALSE),"NO")) -> ISL104 | B23: =IFERROR(__xludf.DUMMYFUNCTION("""COMPUTED_VALUE"""),2) -> 2 | C23: =IFERROR(__xludf.DUMMYFUNCTION("""COMPUTED_VALUE"""),"Ramon Ferrando") -> Ramon Ferrando | D23: =IFERROR(__xludf.DUMMYFUNCTION("""COMPUTED_VALUE"""),"El Albir (Benidorm)") -> El Albir (Benidorm) | E23: =IFERROR(__xludf.DUMMYFUNCTION("""COMPUTED_VALUE"""),"ISL104") -> ISL104 | F23: =IFERROR(__xludf.DUMMYFUNCTION("""COMPUTED_VALUE"""),"Isabel Polo Tomás") -> Isabel Polo Tomás | G23: =IFERROR(__xludf.DUMMYFUNCTION("""COMPUTED_VALUE"""),"TRASLADO TREN") -> TRASLADO TREN | H23: =IFERROR(__xludf.DUMMYFUNCTION("""COMPUTED_VALUE"""),"Traslado") -> Traslado | I23: =IFERROR(__xludf.DUMMYFUNCTION("""COMPUTED_VALUE"""),46063) -> 46063 | J23: =IFERROR(__xludf.DUMMYFUNCTION("""COMPUTED_VALUE"""),46062) -> 46062 | K23: =IFERROR(__xludf.DUMMYFUNCTION("""COMPUTED_VALUE"""),-84.52) -> -84.52 | L23: =IFERROR(__xludf.DUMMYFUNCTION("""COMPUTED_VALUE"""),"AUDICANTE") -> AUDICANTE
A24: =IF(C24="","",IFERROR(VLOOKUP($E24,códigos!$R:$R,1,FALSE),"NO")) -> NO | B24: =IFERROR(__xludf.DUMMYFUNCTION("""COMPUTED_VALUE"""),2) -> 2 | C24: =IFERROR(__xludf.DUMMYFUNCTION("""COMPUTED_VALUE"""),"Maika Blázquez") -> Maika Blázquez | D24: =IFERROR(__xludf.DUMMYFUNCTION("""COMPUTED_VALUE"""),"Getafe") -> Getafe | E24: =IFERROR(__xludf.DUMMYFUNCTION("""COMPUTED_VALUE"""),"MBM26") -> MBM26 | F24: =IFERROR(__xludf.DUMMYFUNCTION("""COMPUTED_VALUE"""),"Gerardo Monedero Rodrigo") -> Gerardo Monedero Rodrigo | G24: =IFERROR(__xludf.DUMMYFUNCTION("""COMPUTED_VALUE"""),"CURSO") -> CURSO | H24: =IFERROR(__xludf.DUMMYFUNCTION("""COMPUTED_VALUE"""),"Inscripción") -> Inscripción | J24: =IFERROR(__xludf.DUMMYFUNCTION("""COMPUTED_VALUE"""),46062) -> 46062 | K24: =IFERROR(__xludf.DUMMYFUNCTION("""COMPUTED_VALUE"""),-609.9) -> -609.9 | L24: =IFERROR(__xludf.DUMMYFUNCTION("""COMPUTED_VALUE"""),"AUDIBRADA") -> AUDIBRADA
A25: =IF(C25="","",IFERROR(VLOOKUP($E25,códigos!$R:$R,1,FALSE),"NO")) -> NO | B25: =IFERROR(__xludf.DUMMYFUNCTION("""COMPUTED_VALUE"""),2) -> 2 | C25: =IFERROR(__xludf.DUMMYFUNCTION("""COMPUTED_VALUE"""),"Maika Blázquez") -> Maika Blázquez | D25: =IFERROR(__xludf.DUMMYFUNCTION("""COMPUTED_VALUE"""),"Getafe") -> Getafe | E25: =IFERROR(__xludf.DUMMYFUNCTION("""COMPUTED_VALUE"""),"MBM96") -> MBM96 | F25: =IFERROR(__xludf.DUMMYFUNCTION("""COMPUTED_VALUE"""),"Beatriz Santos Duque") -> Beatriz Santos Duque | G25: =IFERROR(__xludf.DUMMYFUNCTION("""COMPUTED_VALUE"""),"CURSO") -> CURSO | H25: =IFERROR(__xludf.DUMMYFUNCTION("""COMPUTED_VALUE"""),"Inscripción") -> Inscripción | J25: =IFERROR(__xludf.DUMMYFUNCTION("""COMPUTED_VALUE"""),46062) -> 46062 | K25: =IFERROR(__xludf.DUMMYFUNCTION("""COMPUTED_VALUE"""),-609.9) -> -609.9 | L25: =IFERROR(__xludf.DUMMYFUNCTION("""COMPUTED_VALUE"""),"AUDIBRADA") -> AUDIBRADA
A26: =IF(C26="","",IFERROR(VLOOKUP($E26,códigos!$R:$R,1,FALSE),"NO")) -> NO | B26: =IFERROR(__xludf.DUMMYFUNCTION("""COMPUTED_VALUE"""),2) -> 2 | C26: =IFERROR(__xludf.DUMMYFUNCTION("""COMPUTED_VALUE"""),"Luis Alberto Rodríguez") -> Luis Alberto Rodríguez | D26: =IFERROR(__xludf.DUMMYFUNCTION("""COMPUTED_VALUE"""),"Sevilla- Montoto") -> Sevilla- Montoto | E26: =IFERROR(__xludf.DUMMYFUNCTION("""COMPUTED_VALUE"""),"LAA37") -> LAA37 | F26: =IFERROR(__xludf.DUMMYFUNCTION("""COMPUTED_VALUE"""),"Miguel Rodriguez Pérez") -> Miguel Rodriguez Pérez | G26: =IFERROR(__xludf.DUMMYFUNCTION("""COMPUTED_VALUE"""),"ESTANCIA HOTEL") -> ESTANCIA HOTEL | H26: =IFERROR(__xludf.DUMMYFUNCTION("""COMPUTED_VALUE"""),"Alojamiento") -> Alojamiento | J26: =IFERROR(__xludf.DUMMYFUNCTION("""COMPUTED_VALUE"""),46062) -> 46062 | K26: =IFERROR(__xludf.DUMMYFUNCTION("""COMPUTED_VALUE"""),-980.85) -> -980.85 | L26: =IFERROR(__xludf.DUMMYFUNCTION("""COMPUTED_VALUE"""),"OIR VITAL CENTROS AUDITIVOS ") -> OIR VITAL CENTROS AUDITIVOS
A27: =IF(C27="","",IFERROR(VLOOKUP($E27,códigos!$R:$R,1,FALSE),"NO")) -> ISL104 | B27: =IFERROR(__xludf.DUMMYFUNCTION("""COMPUTED_VALUE"""),2) -> 2 | C27: =IFERROR(__xludf.DUMMYFUNCTION("""COMPUTED_VALUE"""),"Ramon Ferrando") -> Ramon Ferrando | D27: =IFERROR(__xludf.DUMMYFUNCTION("""COMPUTED_VALUE"""),"El Albir (Benidorm)") -> El Albir (Benidorm) | E27: =IFERROR(__xludf.DUMMYFUNCTION("""COMPUTED_VALUE"""),"ISL104") -> ISL104 | F27: =IFERROR(__xludf.DUMMYFUNCTION("""COMPUTED_VALUE"""),"Isabel Polo Tomás") -> Isabel Polo Tomás | G27: =IFERROR(__xludf.DUMMYFUNCTION("""COMPUTED_VALUE"""),"TRASLADO ") -> TRASLADO | H27: =IFERROR(__xludf.DUMMYFUNCTION("""COMPUTED_VALUE"""),"Traslado") -> Traslado | J27: =IFERROR(__xludf.DUMMYFUNCTION("""COMPUTED_VALUE"""),46035) -> 46035 | K27: =IFERROR(__xludf.DUMMYFUNCTION("""COMPUTED_VALUE"""),-68.75) -> -68.75 | L27: =IFERROR(__xludf.DUMMYFUNCTION("""COMPUTED_VALUE"""),"AUDICANTE") -> AUDICANTE
A28: =IF(C28="","",IFERROR(VLOOKUP($E28,códigos!$R:$R,1,FALSE),"NO")) -> ISL104 | B28: =IFERROR(__xludf.DUMMYFUNCTION("""COMPUTED_VALUE"""),2) -> 2 | C28: =IFERROR(__xludf.DUMMYFUNCTION("""COMPUTED_VALUE"""),"Ramon Ferrando") -> Ramon Ferrando | D28: =IFERROR(__xludf.DUMMYFUNCTION("""COMPUTED_VALUE"""),"El Albir (Benidorm)") -> El Albir (Benidorm) | E28: =IFERROR(__xludf.DUMMYFUNCTION("""COMPUTED_VALUE"""),"ISL104") -> ISL104 | F28: =IFERROR(__xludf.DUMMYFUNCTION("""COMPUTED_VALUE"""),"Isabel Polo Tomás") -> Isabel Polo Tomás | G28: =IFERROR(__xludf.DUMMYFUNCTION("""COMPUTED_VALUE"""),"TRASLADO ") -> TRASLADO | H28: =IFERROR(__xludf.DUMMYFUNCTION("""COMPUTED_VALUE"""),"Traslado") -> Traslado | J28: =IFERROR(__xludf.DUMMYFUNCTION("""COMPUTED_VALUE"""),46035) -> 46035 | K28: =IFERROR(__xludf.DUMMYFUNCTION("""COMPUTED_VALUE"""),-630.47) -> -630.47 | L28: =IFERROR(__xludf.DUMMYFUNCTION("""COMPUTED_VALUE"""),"AUDICANTE") -> AUDICANTE
A29: =IF(C29="","",IFERROR(VLOOKUP($E29,códigos!$R:$R,1,FALSE),"NO")) -> NO | B29: =IFERROR(__xludf.DUMMYFUNCTION("""COMPUTED_VALUE"""),2) -> 2 | C29: =IFERROR(__xludf.DUMMYFUNCTION("""COMPUTED_VALUE"""),"Maika Blázquez") -> Maika Blázquez | D29: =IFERROR(__xludf.DUMMYFUNCTION("""COMPUTED_VALUE"""),"Madrid- La Oca") -> Madrid- La Oca | E29: =IFERROR(__xludf.DUMMYFUNCTION("""COMPUTED_VALUE"""),"MBM69") -> MBM69 | F29: =IFERROR(__xludf.DUMMYFUNCTION("""COMPUTED_VALUE"""),"Oscar A, Sánchez Valenzuela") -> Oscar A, Sánchez Valenzuela | G29: =IFERROR(__xludf.DUMMYFUNCTION("""COMPUTED_VALUE"""),"MACBOOK PRO") -> MACBOOK PRO | H29: =IFERROR(__xludf.DUMMYFUNCTION("""COMPUTED_VALUE"""),"Material para centro") -> Material para centro | J29: =IFERROR(__xludf.DUMMYFUNCTION("""COMPUTED_VALUE"""),46065) -> 46065 | K29: =IFERROR(__xludf.DUMMYFUNCTION("""COMPUTED_VALUE"""),-3353.99) -> -3353.99 | L29: =IFERROR(__xludf.DUMMYFUNCTION("""COMPUTED_VALUE"""),"SIEMA BLINK, S.L") -> SIEMA BLINK, S.L
A30: =IF(C30="","",IFERROR(VLOOKUP($E30,códigos!$R:$R,1,FALSE),"NO")) -> NO | B30: =IFERROR(__xludf.DUMMYFUNCTION("""COMPUTED_VALUE"""),2) -> 2 | C30: =IFERROR(__xludf.DUMMYFUNCTION("""COMPUTED_VALUE"""),"Maika Blázquez") -> Maika Blázquez | D30: =IFERROR(__xludf.DUMMYFUNCTION("""COMPUTED_VALUE"""),"Madrid- Canillas") -> Madrid- Canillas | E30: =IFERROR(__xludf.DUMMYFUNCTION("""COMPUTED_VALUE"""),"MBM50") -> MBM50 | F30: =IFERROR(__xludf.DUMMYFUNCTION("""COMPUTED_VALUE"""),"José Gustavo Barroso Braojos") -> José Gustavo Barroso Braojos | G30: =IFERROR(__xludf.DUMMYFUNCTION("""COMPUTED_VALUE"""),"PATROCINIO-VIAJE ISLANDIA") -> PATROCINIO-VIAJE ISLANDIA | H30: =IFERROR(__xludf.DUMMYFUNCTION("""COMPUTED_VALUE"""),"Publicidad") -> Publicidad | I30: =IFERROR(__xludf.DUMMYFUNCTION("""COMPUTED_VALUE"""),46065) -> 46065 | J30: =IFERROR(__xludf.DUMMYFUNCTION("""COMPUTED_VALUE"""),46065) -> 46065 | K30: =IFERROR(__xludf.DUMMYFUNCTION("""COMPUTED_VALUE"""),5025) -> 5025 | L30: =IFERROR(__xludf.DUMMYFUNCTION("""COMPUTED_VALUE"""),"AUDICOST, S.L.U") -> AUDICOST, S.L.U
A31: =IF(C31="","",IFERROR(VLOOKUP($E31,códigos!$R:$R,1,FALSE),"NO")) -> NO | B31: =IFERROR(__xludf.DUMMYFUNCTION("""COMPUTED_VALUE"""),2) -> 2 | C31: =IFERROR(__xludf.DUMMYFUNCTION("""COMPUTED_VALUE"""),"Maika Blázquez") -> Maika Blázquez | D31: =IFERROR(__xludf.DUMMYFUNCTION("""COMPUTED_VALUE"""),"Fuenlabrada") -> Fuenlabrada | E31: =IFERROR(__xludf.DUMMYFUNCTION("""COMPUTED_VALUE"""),"MBM228") -> MBM228 | F31: =IFERROR(__xludf.DUMMYFUNCTION("""COMPUTED_VALUE"""),"Daniel Rodríguez Ocaña") -> Daniel Rodríguez Ocaña | G31: =IFERROR(__xludf.DUMMYFUNCTION("""COMPUTED_VALUE"""),"CURSO") -> CURSO | H31: =IFERROR(__xludf.DUMMYFUNCTION("""COMPUTED_VALUE"""),"Inscripción") -> Inscripción | J31: =IFERROR(__xludf.DUMMYFUNCTION("""COMPUTED_VALUE"""),46066) -> 46066 | K31: =IFERROR(__xludf.DUMMYFUNCTION("""COMPUTED_VALUE"""),-1000) -> -1000 | L31: =IFERROR(__xludf.DUMMYFUNCTION("""COMPUTED_VALUE"""),"AUDIBRADA") -> AUDIBRADA
A32: =IF(C32="","",IFERROR(VLOOKUP($E32,códigos!$R:$R,1,FALSE),"NO")) -> NO | B32: =IFERROR(__xludf.DUMMYFUNCTION("""COMPUTED_VALUE"""),2) -> 2 | C32: =IFERROR(__xludf.DUMMYFUNCTION("""COMPUTED_VALUE"""),"Maika Blázquez") -> Maika Blázquez | D32: =IFERROR(__xludf.DUMMYFUNCTION("""COMPUTED_VALUE"""),"Madrid- Juan Bravo") -> Madrid- Juan Bravo | E32: =IFERROR(__xludf.DUMMYFUNCTION("""COMPUTED_VALUE"""),"MBM229") -> MBM229 | F32: =IFERROR(__xludf.DUMMYFUNCTION("""COMPUTED_VALUE"""),"Raquel de Lama Bermejo") -> Raquel de Lama Bermejo | G32: =IFERROR(__xludf.DUMMYFUNCTION("""COMPUTED_VALUE"""),"CURSO") -> CURSO | H32: =IFERROR(__xludf.DUMMYFUNCTION("""COMPUTED_VALUE"""),"Inscripción") -> Inscripción | J32: =IFERROR(__xludf.DUMMYFUNCTION("""COMPUTED_VALUE"""),46071) -> 46071 | K32: =IFERROR(__xludf.DUMMYFUNCTION("""COMPUTED_VALUE"""),-900) -> -900 | L32: =IFERROR(__xludf.DUMMYFUNCTION("""COMPUTED_VALUE"""),"AUDICOST, S.L.U") -> AUDICOST, S.L.U
A33: =IF(C33="","",IFERROR(VLOOKUP($E33,códigos!$R:$R,1,FALSE),"NO")) -> ISL104 | B33: =IFERROR(__xludf.DUMMYFUNCTION("""COMPUTED_VALUE"""),2) -> 2 | C33: =IFERROR(__xludf.DUMMYFUNCTION("""COMPUTED_VALUE"""),"Ramon Ferrando") -> Ramon Ferrando | D33: =IFERROR(__xludf.DUMMYFUNCTION("""COMPUTED_VALUE"""),"El Albir (Benidorm)") -> El Albir (Benidorm) | E33: =IFERROR(__xludf.DUMMYFUNCTION("""COMPUTED_VALUE"""),"ISL104") -> ISL104 | F33: =IFERROR(__xludf.DUMMYFUNCTION("""COMPUTED_VALUE"""),"Isabel Polo Tomás") -> Isabel Polo Tomás | G33: =IFERROR(__xludf.DUMMYFUNCTION("""COMPUTED_VALUE"""),"VIAJE A JAPON") -> VIAJE A JAPON | H33: =IFERROR(__xludf.DUMMYFUNCTION("""COMPUTED_VALUE"""),"Congreso internacional personal") -> Congreso internacional personal | I33: =IFERROR(__xludf.DUMMYFUNCTION("""COMPUTED_VALUE"""),46078) -> 46078 | J33: =IFERROR(__xludf.DUMMYFUNCTION("""COMPUTED_VALUE"""),46073) -> 46073 | K33: =IFERROR(__xludf.DUMMYFUNCTION("""COMPUTED_VALUE"""),-4957.1) -> -4957.1 | L33: =IFERROR(__xludf.DUMMYFUNCTION("""COMPUTED_VALUE"""),"AUDICANTE") -> AUDICANTE
A34: =IF(C34="","",IFERROR(VLOOKUP($E34,códigos!$R:$R,1,FALSE),"NO")) -> NO | B34: =IFERROR(__xludf.DUMMYFUNCTION("""COMPUTED_VALUE"""),2) -> 2 | C34: =IFERROR(__xludf.DUMMYFUNCTION("""COMPUTED_VALUE"""),"Maika Blázquez") -> Maika Blázquez | D34: =IFERROR(__xludf.DUMMYFUNCTION("""COMPUTED_VALUE"""),"Getafe") -> Getafe | E34: =IFERROR(__xludf.DUMMYFUNCTION("""COMPUTED_VALUE"""),"MBM230") -> MBM230 | F34: =IFERROR(__xludf.DUMMYFUNCTION("""COMPUTED_VALUE"""),"Daniela Carrillo Moreno") -> Daniela Carrillo Moreno | G34: =IFERROR(__xludf.DUMMYFUNCTION("""COMPUTED_VALUE"""),"CURSO") -> CURSO | H34: =IFERROR(__xludf.DUMMYFUNCTION("""COMPUTED_VALUE"""),"Inscripción") -> Inscripción | J34: =IFERROR(__xludf.DUMMYFUNCTION("""COMPUTED_VALUE"""),46078) -> 46078 | K34: =IFERROR(__xludf.DUMMYFUNCTION("""COMPUTED_VALUE"""),-600) -> -600 | L34: =IFERROR(__xludf.DUMMYFUNCTION("""COMPUTED_VALUE"""),"AUDIBRADA") -> AUDIBRADA
A35: =IF(C35="","",IFERROR(VLOOKUP($E35,códigos!$R:$R,1,FALSE),"NO")) -> ISL14 | B35: =IFERROR(__xludf.DUMMYFUNCTION("""COMPUTED_VALUE"""),2) -> 2 | C35: =IFERROR(__xludf.DUMMYFUNCTION("""COMPUTED_VALUE"""),"Iván Sánchez") -> Iván Sánchez | D35: =IFERROR(__xludf.DUMMYFUNCTION("""COMPUTED_VALUE"""),"Orihuela") -> Orihuela | E35: =IFERROR(__xludf.DUMMYFUNCTION("""COMPUTED_VALUE"""),"ISL14") -> ISL14 | F35: =IFERROR(__xludf.DUMMYFUNCTION("""COMPUTED_VALUE"""),"Carlos Velásquez Fermín") -> Carlos Velásquez Fermín | G35: =IFERROR(__xludf.DUMMYFUNCTION("""COMPUTED_VALUE"""),"CERRAMIENTO") -> CERRAMIENTO | H35: =IFERROR(__xludf.DUMMYFUNCTION("""COMPUTED_VALUE"""),"Obras acondicionamiento centro") -> Obras acondicionamiento centro | I35: =IFERROR(__xludf.DUMMYFUNCTION("""COMPUTED_VALUE"""),46063) -> 46063 | K35: =IFERROR(__xludf.DUMMYFUNCTION("""COMPUTED_VALUE"""),-2085.24) -> -2085.24 | L35: =IFERROR(__xludf.DUMMYFUNCTION("""COMPUTED_VALUE"""),"AUDICOST, S.L.U") -> AUDICOST, S.L.U
A36: =IF(C36="","",IFERROR(VLOOKUP($E36,códigos!$R:$R,1,FALSE),"NO")) -> NO | B36: =IFERROR(__xludf.DUMMYFUNCTION("""COMPUTED_VALUE"""),2) -> 2 | C36: =IFERROR(__xludf.DUMMYFUNCTION("""COMPUTED_VALUE"""),"Iván Sánchez") -> Iván Sánchez | D36: =IFERROR(__xludf.DUMMYFUNCTION("""COMPUTED_VALUE"""),"Murcia") -> Murcia | E36: =IFERROR(__xludf.DUMMYFUNCTION("""COMPUTED_VALUE"""),"ISL24") -> ISL24 | F36: =IFERROR(__xludf.DUMMYFUNCTION("""COMPUTED_VALUE"""),"Enrique López Meseguer") -> Enrique López Meseguer | G36: =IFERROR(__xludf.DUMMYFUNCTION("""COMPUTED_VALUE"""),"VIAJE A JORDANIA") -> VIAJE A JORDANIA | H36: =IFERROR(__xludf.DUMMYFUNCTION("""COMPUTED_VALUE"""),"Congreso internacional personal") -> Congreso internacional personal | I36: =IFERROR(__xludf.DUMMYFUNCTION("""COMPUTED_VALUE"""),46056) -> 46056 | K36: =IFERROR(__xludf.DUMMYFUNCTION("""COMPUTED_VALUE"""),-3098) -> -3098 | L36: =IFERROR(__xludf.DUMMYFUNCTION("""COMPUTED_VALUE"""),"AUDICANTE") -> AUDICANTE
A37: =IF(C37="","",IFERROR(VLOOKUP($E37,códigos!$R:$R,1,FALSE),"NO")) -> ISL104 | B37: =IFERROR(__xludf.DUMMYFUNCTION("""COMPUTED_VALUE"""),3) -> 3 | C37: =IFERROR(__xludf.DUMMYFUNCTION("""COMPUTED_VALUE"""),"Ramon Ferrando") -> Ramon Ferrando | D37: =IFERROR(__xludf.DUMMYFUNCTION("""COMPUTED_VALUE"""),"El Albir (Benidorm)") -> El Albir (Benidorm) | E37: =IFERROR(__xludf.DUMMYFUNCTION("""COMPUTED_VALUE"""),"ISL104") -> ISL104 | F37: =IFERROR(__xludf.DUMMYFUNCTION("""COMPUTED_VALUE"""),"Isabel Polo Tomás") -> Isabel Polo Tomás | G37: =IFERROR(__xludf.DUMMYFUNCTION("""COMPUTED_VALUE"""),"HOTEL EN MADRID") -> HOTEL EN MADRID | H37: =IFERROR(__xludf.DUMMYFUNCTION("""COMPUTED_VALUE"""),"Alojamiento") -> Alojamiento | I37: =IFERROR(__xludf.DUMMYFUNCTION("""COMPUTED_VALUE"""),46085) -> 46085 | J37: =IFERROR(__xludf.DUMMYFUNCTION("""COMPUTED_VALUE"""),46084) -> 46084 | K37: =IFERROR(__xludf.DUMMYFUNCTION("""COMPUTED_VALUE"""),-285.73) -> -285.73 | L37: =IFERROR(__xludf.DUMMYFUNCTION("""COMPUTED_VALUE"""),"AUDICANTE") -> AUDICANTE
A38: =IF(C38="","",IFERROR(VLOOKUP($E38,códigos!$R:$R,1,FALSE),"NO")) -> NO | B38: =IFERROR(__xludf.DUMMYFUNCTION("""COMPUTED_VALUE"""),3) -> 3 | C38: =IFERROR(__xludf.DUMMYFUNCTION("""COMPUTED_VALUE"""),"Iván Sánchez") -> Iván Sánchez | D38: =IFERROR(__xludf.DUMMYFUNCTION("""COMPUTED_VALUE"""),"San Javier") -> San Javier | E38: =IFERROR(__xludf.DUMMYFUNCTION("""COMPUTED_VALUE"""),"ISL149") -> ISL149 | F38: =IFERROR(__xludf.DUMMYFUNCTION("""COMPUTED_VALUE"""),"Ángel Onofre Pérez Coll") -> Ángel Onofre Pérez Coll | G38: =IFERROR(__xludf.DUMMYFUNCTION("""COMPUTED_VALUE"""),"INSCRIPCION CURSO RINOPLASTIA") -> INSCRIPCION CURSO RINOPLASTIA | H38: =IFERROR(__xludf.DUMMYFUNCTION("""COMPUTED_VALUE"""),"Inscripción") -> Inscripción | J38: =IFERROR(__xludf.DUMMYFUNCTION("""COMPUTED_VALUE"""),46086) -> 46086 | K38: =IFERROR(__xludf.DUMMYFUNCTION("""COMPUTED_VALUE"""),2176.19) -> 2176.19 | L38: =IFERROR(__xludf.DUMMYFUNCTION("""COMPUTED_VALUE"""),"AUDICOST, S.L.U") -> AUDICOST, S.L.U
A39: =IF(C39="","",IFERROR(VLOOKUP($E39,códigos!$R:$R,1,FALSE),"NO")) -> NO | B39: =IFERROR(__xludf.DUMMYFUNCTION("""COMPUTED_VALUE"""),3) -> 3 | C39: =IFERROR(__xludf.DUMMYFUNCTION("""COMPUTED_VALUE"""),"Lisandro Russian") -> Lisandro Russian | D39: =IFERROR(__xludf.DUMMYFUNCTION("""COMPUTED_VALUE"""),"Logroño") -> Logroño | E39: =IFERROR(__xludf.DUMMYFUNCTION("""COMPUTED_VALUE"""),"LRM249") -> LRM249 | F39: =IFERROR(__xludf.DUMMYFUNCTION("""COMPUTED_VALUE"""),"Daniel Briones Crespo") -> Daniel Briones Crespo | G39: =IFERROR(__xludf.DUMMYFUNCTION("""COMPUTED_VALUE"""),"VIAJE CONGRESO ATENAS") -> VIAJE CONGRESO ATENAS | H39: =IFERROR(__xludf.DUMMYFUNCTION("""COMPUTED_VALUE"""),"Alojamiento y traslado") -> Alojamiento y traslado | I39: =IFERROR(__xludf.DUMMYFUNCTION("""COMPUTED_VALUE"""),46094) -> 46094 | J39: =IFERROR(__xludf.DUMMYFUNCTION("""COMPUTED_VALUE"""),46093) -> 46093 | K39: =IFERROR(__xludf.DUMMYFUNCTION("""COMPUTED_VALUE"""),-4215.86) -> -4215.86 | L39: =IFERROR(__xludf.DUMMYFUNCTION("""COMPUTED_VALUE"""),"AUDICOST LOGROÑO ") -> AUDICOST LOGROÑO
A40: =IF(C40="","",IFERROR(VLOOKUP($E40,códigos!$R:$R,1,FALSE),"NO")) -> NO | B40: =IFERROR(__xludf.DUMMYFUNCTION("""COMPUTED_VALUE"""),3) -> 3 | C40: =IFERROR(__xludf.DUMMYFUNCTION("""COMPUTED_VALUE"""),"Maika Blázquez") -> Maika Blázquez | D40: =IFERROR(__xludf.DUMMYFUNCTION("""COMPUTED_VALUE"""),"Madrid- Canillas") -> Madrid- Canillas | E40: =IFERROR(__xludf.DUMMYFUNCTION("""COMPUTED_VALUE"""),"MBM50") -> MBM50 | F40: =IFERROR(__xludf.DUMMYFUNCTION("""COMPUTED_VALUE"""),"José Gustavo Barroso Braojos") -> José Gustavo Barroso Braojos | G40: =IFERROR(__xludf.DUMMYFUNCTION("""COMPUTED_VALUE"""),"CAMARA ACCION PARA ISLANDIA") -> CAMARA ACCION PARA ISLANDIA | H40: =IFERROR(__xludf.DUMMYFUNCTION("""COMPUTED_VALUE"""),"Publicidad") -> Publicidad | J40: =IFERROR(__xludf.DUMMYFUNCTION("""COMPUTED_VALUE"""),46090) -> 46090 | K40: =IFERROR(__xludf.DUMMYFUNCTION("""COMPUTED_VALUE"""),-699.99) -> -699.99 | L40: =IFERROR(__xludf.DUMMYFUNCTION("""COMPUTED_VALUE"""),"AUDICOST, S.L.U") -> AUDICOST, S.L.U
...

Sheet ENERO
B1: PETICIONES ORL 2026
A3: MES | B3: VISITADOR | C3: CENTRO | D3: COD.CONTRATO | E3: ORL | F3: ACCION MKT | G3: CATEGORÍAS | H3: FECHA P/ | I3: FECHA PETICION | J3: IMPORTE | K3: EMPRESA | L3: OBSERVACIONES
A4: 1 | B4: =IF($E4="","",VLOOKUP(D4,códigos!$F:$G,2,FALSE)) -> Luis Alberto Rodríguez | C4: Jerez de la Frontera | D4: =IF(E4="","",VLOOKUP($E4,códigos!$E:$F,2,FALSE)) -> LAA78 | E4: Maria Del Carmen Salom Coveñas | F4: PATROCINIO | G4: Publicidad | I4: 46034 | J4: -4432 | K4: =IF($C4="","",VLOOKUP(C4,códigos!$B:$C,2,FALSE)) -> AUDICOST, S.L.U | N4: {=INDEX(códigos!E:E,MATCH(D4,códigos!F:F,0))} -> Maria Del Carmen Salom Coveñas
A5: 1 | B5: =IF($E5="","",VLOOKUP(D5,códigos!$F:$G,2,FALSE)) -> Maika Blázquez | C5: Getafe | D5: =IF(E5="","",VLOOKUP($E5,códigos!$E:$F,2,FALSE)) -> MBM149 | E5: María Garrote Garrote | F5: AIRBNB | G5: Alojamiento | H5: 46036 | I5: 46034 | J5: -1700 | K5: =IF($C5="","",VLOOKUP(C5,códigos!$B:$C,2,FALSE)) -> AUDIBRADA | N5: {=INDEX(códigos!E:E,MATCH(D5,códigos!F:F,0))} -> María Garrote Garrote
A6: 1 | B6: =IF($E6="","",VLOOKUP(D6,códigos!$F:$G,2,FALSE)) -> Maika Blázquez | C6: Fuenlabrada | D6: =IF(E6="","",VLOOKUP($E6,códigos!$E:$F,2,FALSE)) -> MBM164 | E6: Paloma Martín-Aragón Martín | F6: INSCRIPCION CURSO MICROCIRUGIA | G6: Inscripción | I6: 46035 | J6: -1663.35 | K6: =IF($C6="","",VLOOKUP(C6,códigos!$B:$C,2,FALSE)) -> AUDIBRADA | N6: {=INDEX(códigos!E:E,MATCH(D6,códigos!F:F,0))} -> Paloma Martín-Aragón Martín
A7: 1 | B7: =IF($E7="","",VLOOKUP(D7,códigos!$F:$G,2,FALSE)) -> Maika Blázquez | C7: Fuenlabrada | D7: =IF(E7="","",VLOOKUP($E7,códigos!$E:$F,2,FALSE)) -> MBM111 | E7: Elisabeth Amarillo Espitia | F7: INSCRIPCION CURSO MICROCIRUGIA | G7: Inscripción | I7: 46035 | J7: -1663.35 | K7: =IF($C7="","",VLOOKUP(C7,códigos!$B:$C,2,FALSE)) -> AUDIBRADA | N7: {=INDEX(códigos!E:E,MATCH(D7,códigos!F:F,0))} -> Elisabeth Amarillo Espitia
A8: 1 | B8: =IF($E8="","",VLOOKUP(D8,códigos!$F:$G,2,FALSE)) -> Maika Blázquez | C8: Madrid- Canillas | D8: =IF(E8="","",VLOOKUP($E8,códigos!$E:$F,2,FALSE)) -> MBM50 | E8: José Gustavo Barroso Braojos | F8: 2 SMARTWATCH | G8: Material para centro | H8: 46036 | I8: 46035 | J8: =-449.99*2 -> -899.98 | K8: =IF($C8="","",VLOOKUP(C8,códigos!$B:$C,2,FALSE)) -> AUDICOST, S.L.U | N8: {=INDEX(códigos!E:E,MATCH(D8,códigos!F:F,0))} -> José Gustavo Barroso Braojos
A9: 1 | B9: =IF($E9="","",VLOOKUP(D9,códigos!$F:$G,2,FALSE)) -> Luis Alberto Rodríguez | C9: Sevilla- Montoto | D9: =IF(E9="","",VLOOKUP($E9,códigos!$E:$F,2,FALSE)) -> LAA08 | E9: David Castro Gutiérrez de Agüero | F9: IPHONE17 PRO | G9: Material para centro | H9: 46042 | I9: 46037 | J9: -1289 | K9: =IF($C9="","",VLOOKUP(C9,códigos!$B:$C,2,FALSE)) -> OIR VITAL CENTROS AUDITIVOS | N9: {=INDEX(códigos!E:E,MATCH(D9,códigos!F:F,0))} -> David Castro Gutiérrez de Agüero
A10: 1 | B10: =IF($E10="","",VLOOKUP(D10,códigos!$F:$G,2,FALSE)) -> Maika Blázquez | C10: Torrejón De Ardoz | D10: =IF(E10="","",VLOOKUP($E10,códigos!$E:$F,2,FALSE)) -> MBM136 | E10: Lorena Sanz López | F10: INSCRIPCION, VUELO Y HOTEL-MAYOR IMPORTE DICBRE. | G10: Inscripción | H10: 46042 | I10: 46041 | J10: -205.75 | K10: =IF($C10="","",VLOOKUP(C10,códigos!$B:$C,2,FALSE)) -> AUDICOST LEGANES | M10: 46003 | N10: {=INDEX(códigos!E:E,MATCH(D10,códigos!F:F,0))} -> Lorena Sanz López
A11: 1 | B11: =IF($E11="","",VLOOKUP(D11,códigos!$F:$G,2,FALSE)) -> Maika Blázquez | C11: Madrid- La Oca | D11: =IF(E11="","",VLOOKUP($E11,códigos!$E:$F,2,FALSE)) -> MBM52 | E11: José Joaquín Gutiérrez Barquín | F11: MESA | G11: Mobiliario | H11: 46044 | I11: 46042 | J11: -973 | K11: =IF($C11="","",VLOOKUP(C11,códigos!$B:$C,2,FALSE)) -> SIEMA BLINK, S.L | N11: {=INDEX(códigos!E:E,MATCH(D11,códigos!F:F,0))} -> José Joaquín Gutiérrez Barquín
A12: 1 | B12: =IF($E12="","",VLOOKUP(D12,códigos!$F:$G,2,FALSE)) -> Maika Blázquez | C12: Fuenlabrada | D12: =IF(E12="","",VLOOKUP($E12,códigos!$E:$F,2,FALSE)) -> MBM190 | E12: Cristina García García | F12: CURSO 2 | G12: Inscripción | I12: 46043 | J12: =-2772.26/2 -> -1386.13 | K12: =IF($C12="","",VLOOKUP(C12,códigos!$B:$C,2,FALSE)) -> AUDIBRADA | N12: {=INDEX(códigos!E:E,MATCH(D12,códigos!F:F,0))} -> Cristina García García
A13: 1 | B13: =IF($E13="","",VLOOKUP(D13,códigos!$F:$G,2,FALSE)) -> Maika Blázquez | C13: Fuenlabrada | D13: =IF(E13="","",VLOOKUP($E13,códigos!$E:$F,2,FALSE)) -> MBM190 | E13: Cristina García García | F13: CURSO 1 | G13: Inscripción | I13: 46043 | J13: =-2772.26/2 -> -1386.13 | K13: =IF($C13="","",VLOOKUP(C13,códigos!$B:$C,2,FALSE)) -> AUDIBRADA | N13: {=INDEX(códigos!E:E,MATCH(D13,códigos!F:F,0))} -> Cristina García García
A14: 1 | B14: =IF($E14="","",VLOOKUP(D14,códigos!$F:$G,2,FALSE)) -> Maika Blázquez | C14: Madrid- Juan Bravo | D14: =IF(E14="","",VLOOKUP($E14,códigos!$E:$F,2,FALSE)) -> MBM224 | E14: Roberto Sanz Garzón | F14: CURSO | G14: Inscripción | H14: 46043 | I14: 46043 | J14: -600 | K14: =IF($C14="","",VLOOKUP(C14,códigos!$B:$C,2,FALSE)) -> AUDICOST, S.L.U | N14: {=INDEX(códigos!E:E,MATCH(D14,códigos!F:F,0))} -> Roberto Sanz Garzón
A15: 1 | B15: =IF($E15="","",VLOOKUP(D15,códigos!$F:$G,2,FALSE)) -> Lisandro Russian | C15: Logroño | D15: =IF(E15="","",VLOOKUP($E15,códigos!$E:$F,2,FALSE)) -> LRM151 | E15: Cristina Ibañez Muñoz | F15: CONGRESO ATENAS | G15: Congreso internacional personal | H15: 46058 | I15: 46044 | J15: -4701.07 | K15: =IF($C15="","",VLOOKUP(C15,códigos!$B:$C,2,FALSE)) -> AUDICOST LOGROÑO | N15: {=INDEX(códigos!E:E,MATCH(D15,códigos!F:F,0))} -> Cristina Ibañez Muñoz
A16: 1 | B16: =IF($E16="","",VLOOKUP(D16,códigos!$F:$G,2,FALSE)) -> Ramon Ferrando | C16: El Albir (Benidorm) | D16: =IF(E16="","",VLOOKUP($E16,códigos!$E:$F,2,FALSE)) -> RFV38 | E16: María Emilia García Ruiz | F16: IPHONE17 | G16: Material para centro | I16: 46045 | J16: -1500 | K16: =IF($C16="","",VLOOKUP(C16,códigos!$B:$C,2,FALSE)) -> AUDICANTE | N16: {=INDEX(códigos!E:E,MATCH(D16,códigos!F:F,0))} -> María Emilia García Ruiz
A17: 1 | B17: =IF($E17="","",VLOOKUP(D17,códigos!$F:$G,2,FALSE)) -> Maika Blázquez | C17: Torrejón De Ardoz | D17: =IF(E17="","",VLOOKUP($E17,códigos!$E:$F,2,FALSE)) -> MBM187 | E17: Abel Bogoya Castaño | F17: CURSO | G17: Inscripción | K17: =IF($C17="","",VLOOKUP(C17,códigos!$B:$C,2,FALSE)) -> AUDICOST LEGANES | N17: {=INDEX(códigos!E:E,MATCH(D17,códigos!F:F,0))} -> Abel Bogoya Castaño
A18: 1 | B18: =IF($E18="","",VLOOKUP(D18,códigos!$F:$G,2,FALSE)) -> Ramon Ferrando | C18: Valencia- Cadiz | D18: =IF(E18="","",VLOOKUP($E18,códigos!$E:$F,2,FALSE)) -> RFV48 | E18: Elena González Turienzo | F18: CURSO | G18: Inscripción | H18: 46058 | I18: 46049 | J18: -133.07 | K18: =IF($C18="","",VLOOKUP(C18,códigos!$B:$C,2,FALSE)) -> AUDICANTE | N18: {=INDEX(códigos!E:E,MATCH(D18,códigos!F:F,0))} -> Elena González Turienzo
A19: 1 | B19: =IF($E19="","",VLOOKUP(D19,códigos!$F:$G,2,FALSE)) | D19: =IF(E19="","",VLOOKUP($E19,códigos!$E:$F,2,FALSE)) | K19: =IF($C19="","",VLOOKUP(C19,códigos!$B:$C,2,FALSE)) | N19: {=INDEX(códigos!E:E,MATCH(D19,códigos!F:F,0))} -> #N/A
A20: 1 | B20: =IF($E20="","",VLOOKUP(D20,códigos!$F:$G,2,FALSE)) | D20: =IF(E20="","",VLOOKUP($E20,códigos!$E:$F,2,FALSE)) | K20: =IF($C20="","",VLOOKUP(C20,códigos!$B:$C,2,FALSE)) | N20: {=INDEX(códigos!E:E,MATCH(D20,códigos!F:F,0))} -> #N/A
A21: 1 | B21: =IF($E21="","",VLOOKUP(D21,códigos!$F:$G,2,FALSE)) | D21: =IF(E21="","",VLOOKUP($E21,códigos!$E:$F,2,FALSE)) | K21: =IF($C21="","",VLOOKUP(C21,códigos!$B:$C,2,FALSE)) | N21: {=INDEX(códigos!E:E,MATCH(D21,códigos!F:F,0))} -> #N/A
A22: 1 | B22: =IF($E22="","",VLOOKUP(D22,códigos!$F:$G,2,FALSE)) | D22: =IF(E22="","",VLOOKUP($E22,códigos!$E:$F,2,FALSE)) | K22: =IF($C22="","",VLOOKUP(C22,códigos!$B:$C,2,FALSE)) | N22: {=INDEX(códigos!E:E,MATCH(D22,códigos!F:F,0))} -> #N/A
A23: 1 | B23: =IF($E23="","",VLOOKUP(D23,códigos!$F:$G,2,FALSE)) | D23: =IF(E23="","",VLOOKUP($E23,códigos!$E:$F,2,FALSE)) | K23: =IF($C23="","",VLOOKUP(C23,códigos!$B:$C,2,FALSE)) | N23: {=INDEX(códigos!E:E,MATCH(D23,códigos!F:F,0))} -> #N/A
A24: 1 | B24: =IF($E24="","",VLOOKUP(D24,códigos!$F:$G,2,FALSE)) | D24: =IF(E24="","",VLOOKUP($E24,códigos!$E:$F,2,FALSE)) | K24: =IF($C24="","",VLOOKUP(C24,códigos!$B:$C,2,FALSE)) | N24: {=INDEX(códigos!E:E,MATCH(D24,códigos!F:F,0))} -> #N/A
A25: 1 | B25: =IF($E25="","",VLOOKUP(D25,códigos!$F:$G,2,FALSE)) | D25: =IF(E25="","",VLOOKUP($E25,códigos!$E:$F,2,FALSE)) | K25: =IF($C25="","",VLOOKUP(C25,códigos!$B:$C,2,FALSE)) | N25: {=INDEX(códigos!E:E,MATCH(D25,códigos!F:F,0))} -> #N/A
E48: ORL
E98: ORL
E148: ORL
E198: ORL
E248: ORL
E298: ORL
E348: ORL
E398: ORL
E448: ORL
E498: ORL
E548: ORL
E598: ORL
... E898: ORL

Sheet FEBRERO
B1: PETICIONES ORL 2026
A3: MES | B3: VISITADOR | C3: CENTRO | D3: COD.CONTRATO | E3: ORL | F3: ACCION MKT | G3: CATEGORÍAS | H3: FECHA P/ | I3: FECHA PETICION | J3: IMPORTE | K3: EMPRESA | L3: OBSERVACIONES
A4: 2 | B4: =IF($E4="","",VLOOKUP(D4,códigos!$F:$G,2,FALSE)) -> Maika Blázquez | C4: Torrejón De Ardoz | D4: =IF(E4="","",VLOOKUP($E4,códigos!$E:$F,2,FALSE)) -> MBM61 | E4: Julie Múñoz Freitez | F4: CURSO | G4: Inscripción | H4: 46062 | I4: 46056 | J4: -2772.25 | K4: =IF($C4="","",VLOOKUP(C4,códigos!$B:$C,2,FALSE)) -> AUDICOST LEGANES | N4: {=INDEX(códigos!E:E,MATCH(D4,códigos!F:F,0))} -> Julie Múñoz Freitez
A5: 2 | B5: =IF($E5="","",VLOOKUP(D5,códigos!$F:$G,2,FALSE)) -> Maika Blázquez | C5: Fuenlabrada | D5: =IF(E5="","",VLOOKUP($E5,códigos!$E:$F,2,FALSE)) -> MBM147 | E5: María Estefanía Hernández García | F5: CURSO | G5: Inscripción | H5: 46064 | I5: 46056 | J5: -443.56 | K5: =IF($C5="","",VLOOKUP(C5,códigos!$B:$C,2,FALSE)) -> AUDIBRADA | N5: {=INDEX(códigos!E:E,MATCH(D5,códigos!F:F,0))} -> María Estefanía Hernández García
A6: 2 | B6: =IF($E6="","",VLOOKUP(D6,códigos!$F:$G,2,FALSE)) -> Ramon Ferrando | C6: Valencia- Parra | D6: =IF(E6="","",VLOOKUP($E6,códigos!$E:$F,2,FALSE)) -> RFV15 | E6: Jean Franco Intraprendente Martini | F6: APPLEWATCH | G6: Material para centro | I6: 46055 | J6: -899 | K6: =IF($C6="","",VLOOKUP(C6,códigos!$B:$C,2,FALSE)) -> AUDICOST, S.L.U | N6: {=INDEX(códigos!E:E,MATCH(D6,códigos!F:F,0))} -> Jean Franco Intraprendente Martini
A7: 2 | B7: =IF($E7="","",VLOOKUP(D7,códigos!$F:$G,2,FALSE)) -> Iván Sánchez | C7: El Albir (Benidorm) | D7: =IF(E7="","",VLOOKUP($E7,códigos!$E:$F,2,FALSE)) -> ISL54 | E7: José María Laborda Margolles | F7: VIAJE A TANZANIA | G7: Congreso internacional | H7: 46059 | I7: 46059 | J7: -4000 | K7: =IF($C7="","",VLOOKUP(C7,códigos!$B:$C,2,FALSE)) -> AUDICANTE | N7: {=INDEX(códigos!E:E,MATCH(D7,códigos!F:F,0))} -> José María Laborda Margolles | P7: PAGADO POR EL
A8: 2 | B8: =IF($E8="","",VLOOKUP(D8,códigos!$F:$G,2,FALSE)) -> Lisandro Russian | C8: Logroño | D8: =IF(E8="","",VLOOKUP($E8,códigos!$E:$F,2,FALSE)) -> LRM264 | E8: Carmen Delgado Muñoz | F8: IPHONE15 | G8: Material para centro | I8: 46049 | J8: -626.99 | K8: =IF($C8="","",VLOOKUP(C8,códigos!$B:$C,2,FALSE)) -> AUDICOST LOGROÑO | N8: {=INDEX(códigos!E:E,MATCH(D8,códigos!F:F,0))} -> Carmen Delgado Muñoz
A9: 1 | B9: =IF($E9="","",VLOOKUP(D9,códigos!$F:$G,2,FALSE)) -> Lisandro Russian | C9: Alcorcón | D9: =IF(E9="","",VLOOKUP($E9,códigos!$E:$F,2,FALSE)) -> LRM82 | E9: José Miguel Aparicio Fernández | F9: CURSO PARA R4 TERESA CONDE GOMEZ-MENOR | G9: Inscripción | H9: 46062 | I9: 46036 | J9: -310.5 | K9: =IF($C9="","",VLOOKUP(C9,códigos!$B:$C,2,FALSE)) -> CLINICA DOS DE MAYO | N9: {=INDEX(códigos!E:E,MATCH(D9,códigos!F:F,0))} -> José Miguel Aparicio Fernández
A10: 2 | B10: =IF($E10="","",VLOOKUP(D10,códigos!$F:$G,2,FALSE)) -> Ramon Ferrando | C10: El Albir (Benidorm) | D10: =IF(E10="","",VLOOKUP($E10,códigos!$E:$F,2,FALSE)) -> ISL104 | E10: Isabel Polo Tomás | F10: TRASLADO TREN | G10: Traslado | H10: 46063 | I10: 46062 | J10: -84.52 | K10: =IF($C10="","",VLOOKUP(C10,códigos!$B:$C,2,FALSE)) -> AUDICANTE | N10: {=INDEX(códigos!E:E,MATCH(D10,códigos!F:F,0))} -> Isabel Polo Tomás
A11: 2 | B11: =IF($E11="","",VLOOKUP(D11,códigos!$F:$G,2,FALSE)) -> Maika Blázquez | C11: Getafe | D11: =IF(E11="","",VLOOKUP($E11,códigos!$E:$F,2,FALSE)) -> MBM26 | E11: Gerardo Monedero Rodrigo | F11: CURSO | G11: Inscripción | I11: 46062 | J11: =-1219.8/2 -> -609.9 | K11: =IF($C11="","",VLOOKUP(C11,códigos!$B:$C,2,FALSE)) -> AUDIBRADA | N11: {=INDEX(códigos!E:E,MATCH(D11,códigos!F:F,0))} -> Gerardo Monedero Rodrigo
A12: 2 | B12: =IF($E12="","",VLOOKUP(D12,códigos!$F:$G,2,FALSE)) -> Maika Blázquez | C12: Getafe | D12: =IF(E12="","",VLOOKUP($E12,códigos!$E:$F,2,FALSE)) -> MBM96 | E12: Beatriz Santos Duque | F12: CURSO | G12: Inscripción | I12: 46062 | J12: =J11 -> -609.9 | K12: =IF($C12="","",VLOOKUP(C12,códigos!$B:$C,2,FALSE)) -> AUDIBRADA | N12: {=INDEX(códigos!E:E,MATCH(D12,códigos!F:F,0))} -> Beatriz Santos Duque
A13: 2 | B13: =IF($E13="","",VLOOKUP(D13,códigos!$F:$G,2,FALSE)) -> Luis Alberto Rodríguez | C13: Sevilla- Montoto | D13: =IF(E13="","",VLOOKUP($E13,códigos!$E:$F,2,FALSE)) -> LAA37 | E13: Miguel Rodriguez Pérez | F13: ESTANCIA HOTEL | G13: Alojamiento | I13: 46062 | J13: -980.85 | K13: =IF($C13="","",VLOOKUP(C13,códigos!$B:$C,2,FALSE)) -> OIR VITAL CENTROS AUDITIVOS | N13: {=INDEX(códigos!E:E,MATCH(D13,códigos!F:F,0))} -> Miguel Rodriguez Pérez
A14: 2 | B14: =IF($E14="","",VLOOKUP(D14,códigos!$F:$G,2,FALSE)) -> Ramon Ferrando | C14: El Albir (Benidorm) | D14: =IF(E14="","",VLOOKUP($E14,códigos!$E:$F,2,FALSE)) -> ISL104 | E14: Isabel Polo Tomás | F14: TRASLADO | G14: Traslado | I14: 46035 | J14: -68.75 | K14: =IF($C14="","",VLOOKUP(C14,códigos!$B:$C,2,FALSE)) -> AUDICANTE | N14: {=INDEX(códigos!E:E,MATCH(D14,códigos!F:F,0))} -> Isabel Polo Tomás
A15: 2 | B15: =IF($E15="","",VLOOKUP(D15,códigos!$F:$G,2,FALSE)) -> Ramon Ferrando | C15: El Albir (Benidorm) | D15: =IF(E15="","",VLOOKUP($E15,códigos!$E:$F,2,FALSE)) -> ISL104 | E15: Isabel Polo Tomás | F15: TRASLADO | G15: Traslado | I15: 46035 | J15: -630.47 | K15: =IF($C15="","",VLOOKUP(C15,códigos!$B:$C,2,FALSE)) -> AUDICANTE | N15: {=INDEX(códigos!E:E,MATCH(D15,códigos!F:F,0))} -> Isabel Polo Tomás
A16: 2 | B16: =IF($E16="","",VLOOKUP(D16,códigos!$F:$G,2,FALSE)) -> Maika Blázquez | C16: Madrid- La Oca | D16: =IF(E16="","",VLOOKUP($E16,códigos!$E:$F,2,FALSE)) -> MBM69 | E16: Oscar A, Sánchez Valenzuela | F16: MACBOOK PRO | G16: Material para centro | I16: 46065 | J16: -3353.99 | K16: =IF($C16="","",VLOOKUP(C16,códigos!$B:$C,2,FALSE)) -> SIEMA BLINK, S.L | N16: {=INDEX(códigos!E:E,MATCH(D16,códigos!F:F,0))} -> Oscar A, Sánchez Valenzuela
A17: 2 | B17: =IF($E17="","",VLOOKUP(D17,códigos!$F:$G,2,FALSE)) -> Maika Blázquez | C17: Madrid- Canillas | D17: =IF(E17="","",VLOOKUP($E17,códigos!$E:$F,2,FALSE)) -> MBM50 | E17: José Gustavo Barroso Braojos | F17: PATROCINIO-VIAJE ISLANDIA | G17: Publicidad | H17: 46065 | I17: 46065 | J17: 5025 | K17: =IF($C17="","",VLOOKUP(C17,códigos!$B:$C,2,FALSE)) -> AUDICOST, S.L.U | N17: {=INDEX(códigos!E:E,MATCH(D17,códigos!F:F,0))} -> José Gustavo Barroso Braojos
A18: 2 | B18: =IF($E18="","",VLOOKUP(D18,códigos!$F:$G,2,FALSE)) -> Maika Blázquez | C18: Fuenlabrada | D18: =IF(E18="","",VLOOKUP($E18,códigos!$E:$F,2,FALSE)) -> MBM228 | E18: Daniel Rodríguez Ocaña | F18: CURSO | G18: Inscripción | I18: 46066 | J18: -1000 | K18: =IF($C18="","",VLOOKUP(C18,códigos!$B:$C,2,FALSE)) -> AUDIBRADA | N18: {=INDEX(códigos!E:E,MATCH(D18,códigos!F:F,0))} -> Daniel Rodríguez Ocaña
A19: 2 | B19: =IF($E19="","",VLOOKUP(D19,códigos!$F:$G,2,FALSE)) -> Maika Blázquez | C19: Madrid- Juan Bravo | D19: =IF(E19="","",VLOOKUP($E19,códigos!$E:$F,2,FALSE)) -> MBM229 | E19: Raquel de Lama Bermejo | F19: CURSO | G19: Inscripción | I19: 46071 | J19: -900 | K19: =IF($C19="","",VLOOKUP(C19,códigos!$B:$C,2,FALSE)) -> AUDICOST, S.L.U | N19: {=INDEX(códigos!E:E,MATCH(D19,códigos!F:F,0))} -> Raquel de Lama Bermejo
A20: 2 | B20: =IF($E20="","",VLOOKUP(D20,códigos!$F:$G,2,FALSE)) -> Ramon Ferrando | C20: El Albir (Benidorm) | D20: =IF(E20="","",VLOOKUP($E20,códigos!$E:$F,2,FALSE)) -> ISL104 | E20: Isabel Polo Tomás | F20: VIAJE A JAPON | G20: Congreso internacional personal | H20: 46078 | I20: 46073 | J20: -4957.1 | K20: =IF($C20="","",VLOOKUP(C20,códigos!$B:$C,2,FALSE)) -> AUDICANTE | N20: {=INDEX(códigos!E:E,MATCH(D20,códigos!F:F,0))} -> Isabel Polo Tomás
A21: 2 | B21: =IF($E21="","",VLOOKUP(D21,códigos!$F:$G,2,FALSE)) -> Maika Blázquez | C21: Getafe | D21: =IF(E21="","",VLOOKUP($E21,códigos!$E:$F,2,FALSE)) -> MBM230 | E21: Daniela Carrillo Moreno | F21: CURSO | G21: Inscripción | I21: 46078 | J21: -600 | K21: =IF($C21="","",VLOOKUP(C21,códigos!$B:$C,2,FALSE)) -> AUDIBRADA | N21: {=INDEX(códigos!E:E,MATCH(D21,códigos!F:F,0))} -> Daniela Carrillo Moreno
A22: 2 | B22: =IF($E22="","",VLOOKUP(D22,códigos!$F:$G,2,FALSE)) -> Iván Sánchez | C22: Orihuela | D22: =IF(E22="","",VLOOKUP($E22,códigos!$E:$F,2,FALSE)) -> ISL14 | E22: Carlos Velásquez Fermín | F22: CERRAMIENTO | G22: Obras acondicionamiento centro | H22: 46063 | J22: -2085.24 | K22: =IF($C22="","",VLOOKUP(C22,códigos!$B:$C,2,FALSE)) -> AUDICOST, S.L.U | N22: {=INDEX(códigos!E:E,MATCH(D22,códigos!F:F,0))} -> Carlos Velásquez Fermín
A23: 2 | B23: =IF($E23="","",VLOOKUP(D23,códigos!$F:$G,2,FALSE)) -> Iván Sánchez | C23: Murcia | D23: =IF(E23="","",VLOOKUP($E23,códigos!$E:$F,2,FALSE)) -> ISL24 | E23: Enrique López Meseguer | F23: VIAJE A JORDANIA | G23: Congreso internacional personal | H23: 46056 | J23: -3098 | K23: =IF($C23="","",VLOOKUP(C23,códigos!$B:$C,2,FALSE)) -> AUDICANTE | M23: 46009 | N23: {=INDEX(códigos!E:E,MATCH(D23,códigos!F:F,0))} -> Enrique López Meseguer
A24: 2 | B24: =IF($E24="","",VLOOKUP(D24,códigos!$F:$G,2,FALSE)) | D24: =IF(E24="","",VLOOKUP($E24,códigos!$E:$F,2,FALSE)) | K24: =IF($C24="","",VLOOKUP(C24,códigos!$B:$C,2,FALSE)) | N24: {=INDEX(códigos!E:E,MATCH(D24,códigos!F:F,0))} -> #N/A
A25: 2 | B25: =IF($E25="","",VLOOKUP(D25,códigos!$F:$G,2,FALSE)) | D25: =IF(E25="","",VLOOKUP($E25,códigos!$E:$F,2,FALSE)) | K25: =IF($C25="","",VLOOKUP(C25,códigos!$B:$C,2,FALSE)) | N25: {=INDEX(códigos!E:E,MATCH(D25,códigos!F:F,0))} -> #N/A
A26: 2 | B26: =IF($E26="","",VLOOKUP(D26,códigos!$F:$G,2,FALSE)) | D26: =IF(E26="","",VLOOKUP($E26,códigos!$E:$F,2,FALSE)) | K26: =IF($C26="","",VLOOKUP(C26,códigos!$B:$C,2,FALSE)) | N26: {=INDEX(códigos!E:E,MATCH(D26,códigos!F:F,0))} -> #N/A
A27: 2 | B27: =IF($E27="","",VLOOKUP(D27,códigos!$F:$G,2,FALSE)) | D27: =IF(E27="","",VLOOKUP($E27,códigos!$E:$F,2,FALSE)) | K27: =IF($C27="","",VLOOKUP(C27,códigos!$B:$C,2,FALSE)) | N27: {=INDEX(códigos!E:E,MATCH(D27,códigos!F:F,0))} -> #N/A
B28: =IF($E28="","",VLOOKUP(D28,códigos!$F:$G,2,FALSE)) | D28: =IF(E28="","",VLOOKUP($E28,códigos!$E:$F,2,FALSE)) | K28: =IF($C28="","",VLOOKUP(C28,códigos!$B:$C,2,FALSE))
B29: =IF($E29="","",VLOOKUP(D29,códigos!$F:$G,2,FALSE)) | D29: =IF(E29="","",VLOOKUP($E29,códigos!$E:$F,2,FALSE)) | K29: =IF($C29="","",VLOOKUP(C29,códigos!$B:$C,2,FALSE))
B30: =IF($E30="","",VLOOKUP(D30,códigos!$F:$G,2,FALSE)) | D30: =IF(E30="","",VLOOKUP($E30,códigos!$E:$F,2,FALSE)) | K30: =IF($C30="","",VLOOKUP(C30,códigos!$B:$C,2,FALSE))

Sheet MARZO
B1: PETICIONES ORL 2026
A3: MES | B3: VISITADOR | C3: CENTRO | D3: COD.CONTRATO | E3: ORL | F3: ACCION MKT | G3: CATEGORÍAS | H3: FECHA P/ | I3: FECHA PETICION | J3: IMPORTE | K3: EMPRESA | L3: OBSERVACIONES
A4: 3 | B4: =IF($E4="","",VLOOKUP(D4,códigos!$F:$G,2,FALSE)) -> Ramon Ferrando | C4: El Albir (Benidorm) | D4: =IF(E4="","",VLOOKUP($E4,códigos!$E:$F,2,FALSE)) -> ISL104 | E4: Isabel Polo Tomás | F4: HOTEL EN MADRID | G4: Alojamiento | H4: 46085 | I4: 46084 | J4: -285.73 | K4: =IF($C4="","",VLOOKUP(C4,códigos!$B:$C,2,FALSE)) -> AUDICANTE | N4: {=INDEX(códigos!E:E,MATCH(D4,códigos!F:F,0))} -> Isabel Polo Tomás
A5: 3 | B5: =IF($E5="","",VLOOKUP(D5,códigos!$F:$G,2,FALSE)) -> Iván Sánchez | C5: San Javier | D5: =IF(E5="","",VLOOKUP($E5,códigos!$E:$F,2,FALSE)) -> ISL149 | E5: Ángel Onofre Pérez Coll | F5: INSCRIPCION CURSO RINOPLASTIA | G5: Inscripción | I5: 46086 | J5: 2176.19 | K5: =IF($C5="","",VLOOKUP(C5,códigos!$B:$C,2,FALSE)) -> AUDICOST, S.L.U | N5: {=INDEX(códigos!E:E,MATCH(D5,códigos!F:F,0))} -> Ángel Onofre Pérez Coll
